Workbook

Sheet Tree condi & Photo num
A5: Tree condition:
B7: A | C7: Good qulity tree/little or no damage/stable tree/healthy canopy
B8: B | C8: Minor defects/minor damage
B9: C | C9: Major defect/Significant impact damage to the main stem /A lack of stability
B10: D | C10: Dying or severely defoliated /Stem decay and hollowing out
A15: Photo Numbers:
B17: photo number | D17: species | G17: Common names
B18: 1 | D18: Lumitzera racemosa | G18: බේරිය
B19: 2 | D19: Avicenia marina | G19: මණ්ඩ
B20: 3 | D20: Rhyzophora | G20: කඩොල්
B21: 4 | D21: Exocaria agallocha | G21: තෙලකීරිය
B22: 5 | D22: Aegicerus corniculatum | G22: හීන් කඩොල්/ ඇවරි කඩොල්
C38: (1)Lumitzera racemosa | I38: (2)Avicenia marina | O38: (3)Aegicerus corniculatum
C58: (4)Exocaria agallocha | I58: (5)Aegicerus corniculatum

Sheet  AGB Calculation
B2: 🔍 1. Understanding the Parameters You Have
B4: DBH (Diameter at Breast Height): in millimeters, so we may need to convert to centimeters or meters, depending on the equation.
B6: Height: in meters.
B8: Number of branches and sub-branches: could be useful if no standard allometric equations fit well and you’re creating a custom model.
B10: Tree Condition (A–D): could act as a correction or quality factor.
B14: 🌱 2. Standard Allometric Equation (General Form)
B16: For mangroves, researchers often use equations like:
B20: Biomass = a × (DBH)^b
B22: or, more complex:
B26: Biomass = a × (DBH^b) × (Height^c)
B28: Where a, b, and c are species-specific constants.
B32: 🧪 3. Sample Equations from Literature for Mangroves
... B110: Here's a table of the species and their typical wood densities (from published literature):
C111: No. | D111: Species Name | E111: Scientific Name | F111: ρ (g/cm³)
C112: 1 | D112: Lumitzera racemosa | E112: Lumnitzera racemosa | F112: 0.7
C113: 2 | D113: Avicennia marina | E113: Avicennia marina | F113: 0.58
C114: 3 | D114: Rhizophora spp. | E114: Rhizophora spp. | F114: 0.62
C115: 4 | D115: Excoecaria agallocha | E115: Excoecaria agallocha | F115: 0.45
C116: 5 | D116: Aegiceras corniculatum | E116: Aegiceras corniculatum | F116: 0.55

Sheet Total biomass,O2 &CO2
B5: 🌿 1. Total Biomass (Above-Ground + Below-Ground)
B7: Mangrove trees store biomass both above and below ground. A common factor to estimate total biomass is to add below-ground biomass (BGB) as a proportion of AGB.
B9: 📌 Typical ratio:
B10: Below-Ground Biomass = 0.24 × AGB (IPCC default value for mangroves)
B12: So:
B14: Total Biomass = AGB + BGB = AGB × (1 + 0.24)
B15: = 406.92 × 1.24 = ~504.58 kg
B19: 🌬️ 2. Oxygen (O₂) Production Estimate
B21: Plants produce oxygen during photosynthesis. A simplified ecological estimate is:
B23: 📌 1 kg of dry biomass = ~1.2 kg of oxygen produced annually
B25: So:
B27: O₂ Produced ≈ 504.58 kg × 1.2 = ~605.5 kg O₂/year
... B39: For mangroves, we can still use:
B41: Parameter | C41: Approximate Conversion
B42: Below-ground biomass | C42: 24% of AGB (IPCC default for mangroves)
B43: O₂ produced | C43: 1 kg biomass → ~1.2 kg O₂/year
B44: CO₂ absorbed | C44: 1 kg biomass → ~1.83 kg CO₂/year
B46: These values are standard and accepted for mangrove ecosystems in global carbon stock studies.

Sheet Summery
B4: ✅ Summary for Plot 1: | F4: ✅ Summary for Plot 2: | J4: ✅ Summary for Plot3: | N4: ✅ Summary for Plot 4: | R4: ✅ Summary for Plot 5:
B6: Item | C6: Value | F6: Item | G6: Value | J6: Item | K6: Value | N6: Item | O6: Value | R6: Item | S6: Value
B7: Adjusted AGB(Kg) | C7: ='Plot 1'!P42 -> 17.37354 | F7: Adjusted AGB(Kg) | G7: ='Plot 2'!P26 -> 67.387459 | J7: Adjusted AGB(Kg) | K7: ='Plot 3'!P67 -> 12.777699 | N7: Adjusted AGB(Kg) | O7: ='Plot 4'!$P$23 -> 4.0045066 | R7: Adjusted AGB(Kg) | S7: ='Plot 5'!P62 -> 124.92141
B8: Estimated Total Biomass(Kg) | C8: ='Plot 1'!P46 -> 21.543189 | F8: Estimated Total Biomass(Kg) | G8: ='Plot 2'!P30 -> 83.56045 | J8: Estimated Total Biomass(Kg) | K8: ='Plot 3'!P71 -> 15.844346 | N8: Estimated Total Biomass(Kg) | O8: ='Plot 4'!$P$27 -> 4.9655882 | R8: Estimated Total Biomass(Kg) | S8: ='Plot 5'!P66 -> 154.90255
B9: Estimated O₂ Produced(Kg/year) | C9: ='Plot 1'!P50 -> 25.851827 | F9: Estimated O₂ Produced(Kg/year) | G9: ='Plot 2'!P34 -> 100.27254 | J9: Estimated O₂ Produced(Kg/year) | K9: ='Plot 3'!P75 -> 19.013216 | N9: Estimated O₂ Produced(Kg/year) | O9: ='Plot 4'!$P$31 -> 5.9587059 | R9: Estimated O₂ Produced(Kg/year) | S9: ='Plot 5'!P70 -> 185.88305
B10: CO₂ Sequestered( kg CO₂/year)≈ | C10: ='Plot 1'!P54 -> 39.424036 | F10: CO₂ Sequestered( kg CO₂/year)≈ | G10: ='Plot 2'!P38 -> 152.91562 | J10: CO₂ Sequestered( kg CO₂/year)≈ | K10: ='Plot 3'!P79 -> 28.995154 | N10: CO₂ Sequestered( kg CO₂/year)≈ | O10: ='Plot 4'!P35 -> 9.0870264 | R10: CO₂ Sequestered( kg CO₂/year)≈ | S10: ='Plot 5'!P74 -> 283.47166
B23: ✅ Summary for Plot 6: | F23: ✅ Summary for Plot 7: | J23: ✅ Summary for Plot 8: | N23: ✅ Summary for Plot 9: | R23: ✅ Summary for Plot 10:
B25: Item | C25: Value | F25: Item | G25: Value | J25: Item | K25: Value | N25: Item | O25: Value | R25: Item | S25: Value
B26: Adjusted AGB(Kg) | C26: ='Plot 6'!P38 -> 14.706278 | F26: Adjusted AGB(Kg) | G26: ='Plot 7'!P51 -> 98.033616 | J26: Adjusted AGB(Kg) | K26: ='Plot 8'!P29 -> 3.9503913 | N26: Adjusted AGB(Kg) | O26: ='Plot 9'!P44 -> 9.1173846 | R26: Adjusted AGB(Kg) | S26: ='Plot 10'!P21 -> 6.9844994
B27: Estimated Total Biomass(Kg) | C27: ='Plot 6'!P42 -> 18.235785 | F27: Estimated Total Biomass(Kg) | G27: ='Plot 7'!P55 -> 121.56168 | J27: Estimated Total Biomass(Kg) | K27: ='Plot 8'!P33 -> 4.8984852 | N27: Estimated Total Biomass(Kg) | O27: ='Plot 9'!P48 -> 11.305557 | R27: Estimated Total Biomass(Kg) | S27: ='Plot 10'!P25 -> 8.6607793
B28: Estimated O₂ Produced(Kg/year) | C28: ='Plot 6'!P46 -> 21.882942 | F28: Estimated O₂ Produced(Kg/year) | G28: ='Plot 7'!P59 -> 145.87402 | J28: Estimated O₂ Produced(Kg/year) | K28: ='Plot 8'!P37 -> 5.8781822 | N28: Estimated O₂ Produced(Kg/year) | O28: ='Plot 9'!P52 -> 13.566668 | R28: Estimated O₂ Produced(Kg/year) | S28: ='Plot 10'!P29 -> 10.392935
B29: CO₂ Sequestered( kg CO₂/year)≈ | C29: ='Plot 6'!P50 -> 33.371487 | F29: CO₂ Sequestered( kg CO₂/year)≈ | G29: ='Plot 7'!P63 -> 222.45788 | J29: CO₂ Sequestered( kg CO₂/year)≈ | K29: ='Plot 8'!P41 -> 8.9642278 | N29: CO₂ Sequestered( kg CO₂/year)≈ | O29: ='Plot 9'!P56 -> 20.689169 | R29: CO₂ Sequestered( kg CO₂/year)≈ | S29: ='Plot 10'!P33 -> 15.849226

Sheet Es CO₂ seq & To adj AGD
B2: ✅ Step-by-Step Conversion
B4: Each plot is 10m x 10m = 100 m²
B5: There are 10,000 m² in 1 hectare → So, each plot is 1/100 of a hectare
B7: That means to get the per hectare value, we multiply the per plot value by 100.
B9: Also, since current units are in kg CO₂/year, we’ll convert to tonnes CO₂/year:
B10: 1 tonne = 1000 kg
B15: 🔢 CO₂ Sequestration per Plot (in tonnes/ha/year) | H15: 📊 Final Summary
B17: Let’s apply: | H17: Average CO₂ sequestration across 10 plots
B19: CO₂ (tonnes/ha/year)= | C19: CO₂ per plot (kg/year)×100​/1000
C21: =CO₂ per plot (kg/year)÷10
C26: Plot | D26: CO₂ Sequestered (kg/year) | E26: CO₂ Sequestered (tonnes/ha/year) | F26: Total Adjusted AGB (Kg/plot)
C27: 1 | D27: =Summery!C10 -> 39.424036 | E27: =D27/10 -> 3.9424036 | F27: ='Plot 1'!P42 -> 17.37354
C28: 2 | D28: =Summery!G10 -> 152.91562 | E28: =D28/10 -> 15.291562 | F28: ='Plot 2'!P26 -> 67.387459
C29: 3 | D29: =Summery!K10 -> 28.995154 | E29: =D29/10 -> 2.8995154 | F29: ='Plot 3'!P67 -> 12.777699
C30: 4 | D30: =Summery!O10 -> 9.0870264 | E30: =D30/10 -> 0.90870264 | F30: ='Plot 4'!P23 -> 4.0045066
C31: 5 | D31: =Summery!S10 -> 283.47166 | E31: =D31/10 -> 28.347166 | F31: ='Plot 5'!P62 -> 124.92141
C32: 6 | D32: =Summery!C29 -> 33.371487 | E32: =D32/10 -> 3.3371487 | F32: ='Plot 6'!P38 -> 14.706278
C33: 7 | D33: =Summery!G29 -> 222.45788 | E33: =D33/10 -> 22.245788 | F33: ='Plot 7'!P51 -> 98.033616
C34: 8 | D34: =Summery!K29 -> 8.9642278 | E34: =D34/10 -> 0.89642278 | F34: ='Plot 8'!P29 -> 3.9503913
C35: 9 | D35: =Summery!O29 -> 20.689169 | E35: =D35/10 -> 2.0689169 | F35: ='Plot 9'!P44 -> 9.1173846
C36: 10 | D36: =Summery!S29 -> 15.849226 | E36: =D36/10 -> 1.5849226 | F36: ='Plot 10'!P21 -> 6.9844994
D38: Average CO₂ sequestration across 10 plots: | E38: =AVERAGE(Table1[CO₂ Sequestered (tonnes/ha/year)]) -> 8.1522549 | F38: tonnes/ha/year
D39: Total Adjusted AGB (Kg) | E39: =SUM(Table1[Total Adjusted AGB (Kg/plot)]) -> 359.25678 | F39: Kg
D42: Here, there was a part of the lagoon that had been destroyed by fire, an area with well-grown mangrove, as well as areas with small mangrove trees that had been burned under reforestation, and areas with mangrove trees in normal condition. It was prepared based on data obtained from 10 10m * 10m plots selected to cover all.(But in addition, if there were data on the areas under each condition and measurements of the total area, this could be more successful.)

Sheet Plot 1
A1: Kalpitiya Mangrove Inventory
A2: Date:03/2025
A3: Plot No | B3: Tag No | C3: Common Name | D3: Scientific Name | E3: DBH(mm) | F3: Tree Height(m) | G3: Tree Condition(A-D) | H3: Presence of Flowers/Fruits | I3: GPS | J3: Photo Numbers | K3: sub branchers (sb) | L3: branchers(b) | O3: ADG(kg/Tree) | P3: Adjusted AGB(for condition)(kg) | R3: Tree Condition Value | T3: Standadize Tree Condition
A4: 1 | B4: 1 | C4: =IF(J4=1,"බේරිය",IF(J4=2,"මණ්ඩ",IF(J4=3,"කඩොල්",IF(J4=4,"තෙලකීරිය","හීන් කඩොල්/ ඇවරි කඩොල්")))) -> බේරිය | D4: =IF(J4=1,"Lumitzera racemosa",IF(J4=2,"Avicenia marina",IF(J4=3,"Rhizophora spp.",IF(J4=4,"Excoecaria agallocha","Aegiceras corniculatum")))) -> Lumitzera racemosa | E4: 10.57 | F4: 0.58 | G4: B | J4: 1 | K4: 8 | L4: 12 | O4: =0.251*(IF(J4=1,0.7,IF(J4=2,0.58,IF(J4=3,0.62,IF(J4=4,0.45,0.55))))*E4/10*F4)^0.916 -> 0.1156475 | P4: =O4*IF(G4="A",1,IF(G4="B",0.9,IF(G4="C",0.75,0.5))) -> 0.10408275 | R4: =IF(G4="A",1,IF(G4="B",0.9,IF(G4="C",0.75,0.5))) -> 0.9 | T4: =STANDARDIZE(R4,$R$42,$R$43) -> -0.58449446
B5: 2 | C5: =IF(J5=1,"බේරිය",IF(J5=2,"මණ්ඩ",IF(J5=3,"කඩොල්",IF(J5=4,"තෙලකීරිය","හීන් කඩොල්/ ඇවරි කඩොල්")))) -> බේරිය | D5: =IF(J5=1,"Lumitzera racemosa",IF(J5=2,"Avicenia marina",IF(J5=3,"Rhizophora spp.",IF(J5=4,"Excoecaria agallocha","Aegiceras corniculatum")))) -> Lumitzera racemosa | E5: 6.24 | F5: 0.55 | G5: B | J5: 1 | K5: 6 | L5: 8 | O5: =0.251*(IF(J5=1,0.7,IF(J5=2,0.58,IF(J5=3,0.62,IF(J5=4,0.45,0.55))))*E5/10*F5)^0.916 -> 0.067974314 | P5: =O5*IF(G5="A",1,IF(G5="B",0.9,IF(G5="C",0.75,0.5))) -> 0.061176883 | R5: =IF(G5="A",1,IF(G5="B",0.9,IF(G5="C",0.75,0.5))) -> 0.9 | T5: =STANDARDIZE(R5,$R$42,$R$43) -> -0.58449446
B6: 2 | C6: =IF(J6=1,"බේරිය",IF(J6=2,"මණ්ඩ",IF(J6=3,"කඩොල්",IF(J6=4,"තෙලකීරිය","හීන් කඩොල්/ ඇවරි කඩොල්")))) -> බේරිය | D6: =IF(J6=1,"Lumitzera racemosa",IF(J6=2,"Avicenia marina",IF(J6=3,"Rhizophora spp.",IF(J6=4,"Excoecaria agallocha","Aegiceras corniculatum")))) -> Lumitzera racemosa | E6: 15.46 | F6: 0.56 | G6: B | J6: 1 | K6: 8 | L6: 6 | O6: =0.251*(IF(J6=1,0.7,IF(J6=2,0.58,IF(J6=3,0.62,IF(J6=4,0.45,0.55))))*E6/10*F6)^0.916 -> 0.15864984 | P6: =O6*IF(G6="A",1,IF(G6="B",0.9,IF(G6="C",0.75,0.5))) -> 0.14278486 | R6: =IF(G6="A",1,IF(G6="B",0.9,IF(G6="C",0.75,0.5))) -> 0.9 | T6: =STANDARDIZE(R6,$R$42,$R$43) -> -0.58449446
B7: 3 | C7: =IF(J7=1,"බේරිය",IF(J7=2,"මණ්ඩ",IF(J7=3,"කඩොල්",IF(J7=4,"තෙලකීරිය","හීන් කඩොල්/ ඇවරි කඩොල්")))) -> බේරිය | D7: =IF(J7=1,"Lumitzera racemosa",IF(J7=2,"Avicenia marina",IF(J7=3,"Rhizophora spp.",IF(J7=4,"Excoecaria agallocha","Aegiceras corniculatum")))) -> Lumitzera racemosa | E7: 8.99 | F7: 0.43 | G7: B | J7: 1 | K7: 9 | L7: 7 | O7: =0.251*(IF(J7=1,0.7,IF(J7=2,0.58,IF(J7=3,0.62,IF(J7=4,0.45,0.55))))*E7/10*F7)^0.916 -> 0.075802671 | P7: =O7*IF(G7="A",1,IF(G7="B",0.9,IF(G7="C",0.75,0.5))) -> 0.068222404 | R7: =IF(G7="A",1,IF(G7="B",0.9,IF(G7="C",0.75,0.5))) -> 0.9 | T7: =STANDARDIZE(R7,$R$42,$R$43) -> -0.58449446
B8: 4 | C8: =IF(J8=1,"බේරිය",IF(J8=2,"මණ්ඩ",IF(J8=3,"කඩොල්",IF(J8=4,"තෙලකීරිය","හීන් කඩොල්/ ඇවරි කඩොල්")))) -> බේරිය | D8: =IF(J8=1,"Lumitzera racemosa",IF(J8=2,"Avicenia marina",IF(J8=3,"Rhizophora spp.",IF(J8=4,"Excoecaria agallocha","Aegiceras corniculatum")))) -> Lumitzera racemosa | E8: 7.59 | F8: 0.56 | G8: B | J8: 1 | K8: 6 | L8: 11 | O8: =0.251*(IF(J8=1,0.7,IF(J8=2,0.58,IF(J8=3,0.62,IF(J8=4,0.45,0.55))))*E8/10*F8)^0.916 -> 0.082684713 | P8: =O8*IF(G8="A",1,IF(G8="B",0.9,IF(G8="C",0.75,0.5))) -> 0.074416242 | R8: =IF(G8="A",1,IF(G8="B",0.9,IF(G8="C",0.75,0.5))) -> 0.9 | T8: =STANDARDIZE(R8,$R$42,$R$43) -> -0.58449446
B9: 5 | C9: =IF(J9=1,"බේරිය",IF(J9=2,"මණ්ඩ",IF(J9=3,"කඩොල්",IF(J9=4,"තෙලකීරිය","හීන් කඩොල්/ ඇවරි කඩොල්")))) -> බේරිය | D9: =IF(J9=1,"Lumitzera racemosa",IF(J9=2,"Avicenia marina",IF(J9=3,"Rhizophora spp.",IF(J9=4,"Excoecaria agallocha","Aegiceras corniculatum")))) -> Lumitzera racemosa | E9: 5.98 | F9: 0.44 | G9: B | J9: 1 | K9: 4 | L9: 6 | O9: =0.251*(IF(J9=1,0.7,IF(J9=2,0.58,IF(J9=3,0.62,IF(J9=4,0.45,0.55))))*E9/10*F9)^0.916 -> 0.053289846 | P9: =O9*IF(G9="A",1,IF(G9="B",0.9,IF(G9="C",0.75,0.5))) -> 0.047960861 | R9: =IF(G9="A",1,IF(G9="B",0.9,IF(G9="C",0.75,0.5))) -> 0.9 | T9: =STANDARDIZE(R9,$R$42,$R$43) -> -0.58449446
B10: 6 | C10: =IF(J10=1,"බේරිය",IF(J10=2,"මණ්ඩ",IF(J10=3,"කඩොල්",IF(J10=4,"තෙලකීරිය","හීන් කඩොල්/ ඇවරි කඩොල්")))) -> මණ්ඩ | D10: =IF(J10=1,"Lumitzera racemosa",IF(J10=2,"Avicenia marina",IF(J10=3,"Rhizophora spp.",IF(J10=4,"Excoecaria agallocha","Aegiceras corniculatum")))) -> Avicenia marina | E10: 8.57 | F10: 0.76 | G10: A | J10: 2 | K10: 3 | L10: 12 | O10: =0.251*(IF(J10=1,0.7,IF(J10=2,0.58,IF(J10=3,0.62,IF(J10=4,0.45,0.55))))*E10/10*F10)^0.916 -> 0.1028986 | P10: =O10*IF(G10="A",1,IF(G10="B",0.9,IF(G10="C",0.75,0.5))) -> 0.1028986 | R10: =IF(G10="A",1,IF(G10="B",0.9,IF(G10="C",0.75,0.5))) -> 1 | T10: =STANDARDIZE(R10,$R$42,$R$43) -> 1.1456091
B11: 7 | C11: =IF(J11=1,"බේරිය",IF(J11=2,"මණ්ඩ",IF(J11=3,"කඩොල්",IF(J11=4,"තෙලකීරිය","හීන් කඩොල්/ ඇවරි කඩොල්")))) -> බේරිය | D11: =IF(J11=1,"Lumitzera racemosa",IF(J11=2,"Avicenia marina",IF(J11=3,"Rhizophora spp.",IF(J11=4,"Excoecaria agallocha","Aegiceras corniculatum")))) -> Lumitzera racemosa | E11: 9.22 | F11: 0.58 | G11: A | J11: 1 | K11: 10 | L11: 7 | O11: =0.251*(IF(J11=1,0.7,IF(J11=2,0.58,IF(J11=3,0.62,IF(J11=4,0.45,0.55))))*E11/10*F11)^0.916 -> 0.10204156 | P11: =O11*IF(G11="A",1,IF(G11="B",0.9,IF(G11="C",0.75,0.5))) -> 0.10204156 | R11: =IF(G11="A",1,IF(G11="B",0.9,IF(G11="C",0.75,0.5))) -> 1 | T11: =STANDARDIZE(R11,$R$42,$R$43) -> 1.1456091
B12: 8 | C12: =IF(J12=1,"බේරිය",IF(J12=2,"මණ්ඩ",IF(J12=3,"කඩොල්",IF(J12=4,"තෙලකීරිය","හීන් කඩොල්/ ඇවරි කඩොල්")))) -> බේරිය | D12: =IF(J12=1,"Lumitzera racemosa",IF(J12=2,"Avicenia marina",IF(J12=3,"Rhizophora spp.",IF(J12=4,"Excoecaria agallocha","Aegiceras corniculatum")))) -> Lumitzera racemosa | E12: 8.33 | F12: 0.41 | G12: B | J12: 1 | K12: 2 | L12: 7 | O12: =0.251*(IF(J12=1,0.7,IF(J12=2,0.58,IF(J12=3,0.62,IF(J12=4,0.45,0.55))))*E12/10*F12)^0.916 -> 0.067671275 | P12: =O12*IF(G12="A",1,IF(G12="B",0.9,IF(G12="C",0.75,0.5))) -> 0.060904148 | R12: =IF(G12="A",1,IF(G12="B",0.9,IF(G12="C",0.75,0.5))) -> 0.9 | T12: =STANDARDIZE(R12,$R$42,$R$43) -> -0.58449446
B13: 9 | C13: =IF(J13=1,"බේරිය",IF(J13=2,"මණ්ඩ",IF(J13=3,"කඩොල්",IF(J13=4,"තෙලකීරිය","හීන් කඩොල්/ ඇවරි කඩොල්")))) -> බේරිය | D13: =IF(J13=1,"Lumitzera racemosa",IF(J13=2,"Avicenia marina",IF(J13=3,"Rhizophora spp.",IF(J13=4,"Excoecaria agallocha","Aegiceras corniculatum")))) -> Lumitzera racemosa | E13: 13.71 | F13: 0.81 | G13: B | J13: 1 | K13: 9 | L13: 13 | O13: =0.251*(IF(J13=1,0.7,IF(J13=2,0.58,IF(J13=3,0.62,IF(J13=4,0.45,0.55))))*E13/10*F13)^0.916 -> 0.19928844 | P13: =O13*IF(G13="A",1,IF(G13="B",0.9,IF(G13="C",0.75,0.5))) -> 0.1793596 | R13: =IF(G13="A",1,IF(G13="B",0.9,IF(G13="C",0.75,0.5))) -> 0.9 | T13: =STANDARDIZE(R13,$R$42,$R$43) -> -0.58449446
B14: 10 | C14: =IF(J14=1,"බේරිය",IF(J14=2,"මණ්ඩ",IF(J14=3,"කඩොල්",IF(J14=4,"තෙලකීරිය","හීන් කඩොල්/ ඇවරි කඩොල්")))) -> බේරිය | D14: =IF(J14=1,"Lumitzera racemosa",IF(J14=2,"Avicenia marina",IF(J14=3,"Rhizophora spp.",IF(J14=4,"Excoecaria agallocha","Aegiceras corniculatum")))) -> Lumitzera racemosa | E14: 15.99 | F14: 0.66 | G14: B | J14: 1 | K14: 15 | L14: 6 | O14: =0.251*(IF(J14=1,0.7,IF(J14=2,0.58,IF(J14=3,0.62,IF(J14=4,0.45,0.55))))*E14/10*F14)^0.916 -> 0.1902002 | P14: =O14*IF(G14="A",1,IF(G14="B",0.9,IF(G14="C",0.75,0.5))) -> 0.17118018 | R14: =IF(G14="A",1,IF(G14="B",0.9,IF(G14="C",0.75,0.5))) -> 0.9 | T14: =STANDARDIZE(R14,$R$42,$R$43) -> -0.58449446
B15: 11 | C15: =IF(J15=1,"බේරිය",IF(J15=2,"මණ්ඩ",IF(J15=3,"කඩොල්",IF(J15=4,"තෙලකීරිය","හීන් කඩොල්/ ඇවරි කඩොල්")))) -> බේරිය | D15: =IF(J15=1,"Lumitzera racemosa",IF(J15=2,"Avicenia marina",IF(J15=3,"Rhizophora spp.",IF(J15=4,"Excoecaria agallocha","Aegiceras corniculatum")))) -> Lumitzera racemosa | E15: 11.88 | F15: 0.75 | G15: B | J15: 1 | K15: 12 | L15: 11 | O15: =0.251*(IF(J15=1,0.7,IF(J15=2,0.58,IF(J15=3,0.62,IF(J15=4,0.45,0.55))))*E15/10*F15)^0.916 -> 0.1628814 | P15: =O15*IF(G15="A",1,IF(G15="B",0.9,IF(G15="C",0.75,0.5))) -> 0.14659326 | R15: =IF(G15="A",1,IF(G15="B",0.9,IF(G15="C",0.75,0.5))) -> 0.9 | T15: =STANDARDIZE(R15,$R$42,$R$43) -> -0.58449446
B16: 12 | C16: =IF(J16=1,"බේරිය",IF(J16=2,"මණ්ඩ",IF(J16=3,"කඩොල්",IF(J16=4,"තෙලකීරිය","හීන් කඩොල්/ ඇවරි කඩොල්")))) -> බේරිය | D16: =IF(J16=1,"Lumitzera racemosa",IF(J16=2,"Avicenia marina",IF(J16=3,"Rhizophora spp.",IF(J16=4,"Excoecaria agallocha","Aegiceras corniculatum")))) -> Lumitzera racemosa | E16: 13.68 | F16: 0.76 | G16: B | J16: 1 | K16: 7 | L16: 13 | O16: =0.251*(IF(J16=1,0.7,IF(J16=2,0.58,IF(J16=3,0.62,IF(J16=4,0.45,0.55))))*E16/10*F16)^0.916 -> 0.18761331 | P16: =O16*IF(G16="A",1,IF(G16="B",0.9,IF(G16="C",0.75,0.5))) -> 0.16885198 | R16: =IF(G16="A",1,IF(G16="B",0.9,IF(G16="C",0.75,0.5))) -> 0.9 | T16: =STANDARDIZE(R16,$R$42,$R$43) -> -0.58449446
... B40: 37 | C40: =IF(J40=1,"බේරිය",IF(J40=2,"මණ්ඩ",IF(J40=3,"කඩොල්",IF(J40=4,"තෙලකීරිය","හීන් කඩොල්/ ඇවරි කඩොල්")))) -> හීන් කඩොල්/ ඇවරි කඩොල් | D40: =IF(J40=1,"Lumitzera racemosa",IF(J40=2,"Avicenia marina",IF(J40=3,"Rhizophora spp.",IF(J40=4,"Excoecaria agallocha","Aegiceras corniculatum")))) -> Aegiceras corniculatum | E40: 12.8 | F40: 0.94 | G40: B | J40: 5 | K40: 1 | L40: 13 | O40: =0.251*(IF(J40=1,0.7,IF(J40=2,0.58,IF(J40=3,0.62,IF(J40=4,0.45,0.55))))*E40/10*F40)^0.916 -> 0.17196315 | P40: =O40*IF(G40="A",1,IF(G40="B",0.9,IF(G40="C",0.75,0.5))) -> 0.15476683 | R40: =IF(G40="A",1,IF(G40="B",0.9,IF(G40="C",0.75,0.5))) -> 0.9 | T40: =STANDARDIZE(R40,$R$42,$R$43) -> -0.58449446
O42: Total Adjusted AGB (Kg/plot) | P42: =SUM(P4:P40) -> 17.37354 | Q42: Avarage Tree Condition value | R42: =AVERAGE(R4:R40) -> 0.93378378
Q43: STDEV | R43: =STDEV(R4:R40) -> 0.057800007
O45: Total Biomass = AGB + BGB = AGB × (1 + 0.24)
O46: Total Biomass | P46: =P42*1.24 -> 21.543189
O49: 1 kg of dry biomass = ~1.2 kg of oxygen produced annually
O50: O₂ Produced( kg O₂/year)≈ | P50: =P46*1.2 -> 25.851827
O53: CO₂ absorbed | P53: 1 kg biomass → ~1.83 kg CO₂/year
O54: CO₂ Sequestered( kg CO₂/year)≈ | P54: =1.83*P46 -> 39.424036

Sheet Plot 2
A1: Kalpitiya Mangrove Inventory
A2: Date:03/2025
A3: Plot No | B3: Tag No | C3: Common Name | D3: Scientific Name | E3: DBH(mm) | F3: Tree Height(m) | G3: Tree Condition(A-D) | H3: Presence of Flowers/Fruits | I3: GPS | J3: Photo Numbers | K3: sub branchers (sb) | L3: branchers(b) | O3: ADG(kg/Tree) | P3: Adjusted AGB(for condition)(kg) | R3: Tree Condition Value | T3: Standadize Tree Condition
A4: 2 | B4: 38 | C4: =IF(J4=1,"බේරිය",IF(J4=2,"මණ්ඩ",IF(J4=3,"කඩොල්",IF(J4=4,"තෙලකීරිය","හීන් කඩොල්/ ඇවරි කඩොල්")))) -> තෙලකීරිය | D4: =IF(J4=1,"Lumitzera racemosa",IF(J4=2,"Avicenia marina",IF(J4=3,"Rhizophora spp.",IF(J4=4,"Excoecaria agallocha","Aegiceras corniculatum")))) -> Excoecaria agallocha | E4: 40.78 | F4: 2.38 | G4: A | J4: 4 | K4: 11 | L4: 7 | O4: =0.251*(IF(J4=1,0.7,IF(J4=2,0.58,IF(J4=3,0.62,IF(J4=4,0.45,0.55))))*E4/10*F4)^0.916 -> 0.96856893 | P4: =O4*IF(G4="A",1,IF(G4="B",0.9,IF(G4="C",0.75,0.5))) -> 0.96856893 | R4: =IF(G4="A",1,IF(G4="B",0.9,IF(G4="C",0.75,0.5))) -> 1 | T4: =STANDARDIZE(R4,$R$26,$R$27) -> 0.5665927
B5: 39 | C5: =IF(J5=1,"බේරිය",IF(J5=2,"මණ්ඩ",IF(J5=3,"කඩොල්",IF(J5=4,"තෙලකීරිය","හීන් කඩොල්/ ඇවරි කඩොල්")))) -> බේරිය | D5: =IF(J5=1,"Lumitzera racemosa",IF(J5=2,"Avicenia marina",IF(J5=3,"Rhizophora spp.",IF(J5=4,"Excoecaria agallocha","Aegiceras corniculatum")))) -> Lumitzera racemosa | E5: 17.9 | F5: 3.81 | G5: A | J5: 1 | K5: 15 | L5: 12 | O5: =0.251*(IF(J5=1,0.7,IF(J5=2,0.58,IF(J5=3,0.62,IF(J5=4,0.45,0.55))))*E5/10*F5)^0.916 -> 1.05081 | P5: =O5*IF(G5="A",1,IF(G5="B",0.9,IF(G5="C",0.75,0.5))) -> 1.05081 | R5: =IF(G5="A",1,IF(G5="B",0.9,IF(G5="C",0.75,0.5))) -> 1 | T5: =STANDARDIZE(R5,$R$26,$R$27) -> 0.5665927
B6: 40 | C6: =IF(J6=1,"බේරිය",IF(J6=2,"මණ්ඩ",IF(J6=3,"කඩොල්",IF(J6=4,"තෙලකීරිය","හීන් කඩොල්/ ඇවරි කඩොල්")))) -> බේරිය | D6: =IF(J6=1,"Lumitzera racemosa",IF(J6=2,"Avicenia marina",IF(J6=3,"Rhizophora spp.",IF(J6=4,"Excoecaria agallocha","Aegiceras corniculatum")))) -> Lumitzera racemosa | E6: 39.97 | F6: 1.73 | G6: A | J6: 1 | K6: 10 | L6: 4 | O6: =0.251*(IF(J6=1,0.7,IF(J6=2,0.58,IF(J6=3,0.62,IF(J6=4,0.45,0.55))))*E6/10*F6)^0.916 -> 1.0641975 | P6: =O6*IF(G6="A",1,IF(G6="B",0.9,IF(G6="C",0.75,0.5))) -> 1.0641975 | R6: =IF(G6="A",1,IF(G6="B",0.9,IF(G6="C",0.75,0.5))) -> 1 | T6: =STANDARDIZE(R6,$R$26,$R$27) -> 0.5665927
B7: 41 | C7: =IF(J7=1,"බේරිය",IF(J7=2,"මණ්ඩ",IF(J7=3,"කඩොල්",IF(J7=4,"තෙලකීරිය","හීන් කඩොල්/ ඇවරි කඩොල්")))) -> බේරිය | D7: =IF(J7=1,"Lumitzera racemosa",IF(J7=2,"Avicenia marina",IF(J7=3,"Rhizophora spp.",IF(J7=4,"Excoecaria agallocha","Aegiceras corniculatum")))) -> Lumitzera racemosa | E7: 12.98 | F7: 1.42 | G7: A | J7: 1 | K7: 12 | L7: 7 | O7: =0.251*(IF(J7=1,0.7,IF(J7=2,0.58,IF(J7=3,0.62,IF(J7=4,0.45,0.55))))*E7/10*F7)^0.916 -> 0.31698541 | P7: =O7*IF(G7="A",1,IF(G7="B",0.9,IF(G7="C",0.75,0.5))) -> 0.31698541 | R7: =IF(G7="A",1,IF(G7="B",0.9,IF(G7="C",0.75,0.5))) -> 1 | T7: =STANDARDIZE(R7,$R$26,$R$27) -> 0.5665927
B8: 42 | C8: =IF(J8=1,"බේරිය",IF(J8=2,"මණ්ඩ",IF(J8=3,"කඩොල්",IF(J8=4,"තෙලකීරිය","හීන් කඩොල්/ ඇවරි කඩොල්")))) -> බේරිය | D8: =IF(J8=1,"Lumitzera racemosa",IF(J8=2,"Avicenia marina",IF(J8=3,"Rhizophora spp.",IF(J8=4,"Excoecaria agallocha","Aegiceras corniculatum")))) -> Lumitzera racemosa | E8: 9.3 | F8: 0.99 | G8: B | J8: 1 | K8: 7 | L8: 13 | O8: =0.251*(IF(J8=1,0.7,IF(J8=2,0.58,IF(J8=3,0.62,IF(J8=4,0.45,0.55))))*E8/10*F8)^0.916 -> 0.16784784 | P8: =O8*IF(G8="A",1,IF(G8="B",0.9,IF(G8="C",0.75,0.5))) -> 0.15106305 | R8: =IF(G8="A",1,IF(G8="B",0.9,IF(G8="C",0.75,0.5))) -> 0.9 | T8: =STANDARDIZE(R8,$R$26,$R$27) -> -0.22663708
B9: 43 | C9: =IF(J9=1,"බේරිය",IF(J9=2,"මණ්ඩ",IF(J9=3,"කඩොල්",IF(J9=4,"තෙලකීරිය","හීන් කඩොල්/ ඇවරි කඩොල්")))) -> බේරිය | D9: =IF(J9=1,"Lumitzera racemosa",IF(J9=2,"Avicenia marina",IF(J9=3,"Rhizophora spp.",IF(J9=4,"Excoecaria agallocha","Aegiceras corniculatum")))) -> Lumitzera racemosa | E9: 12.23 | F9: 0.84 | G9: B | J9: 1 | K9: 4 | L9: 12 | O9: =0.251*(IF(J9=1,0.7,IF(J9=2,0.58,IF(J9=3,0.62,IF(J9=4,0.45,0.55))))*E9/10*F9)^0.916 -> 0.18556924 | P9: =O9*IF(G9="A",1,IF(G9="B",0.9,IF(G9="C",0.75,0.5))) -> 0.16701232 | R9: =IF(G9="A",1,IF(G9="B",0.9,IF(G9="C",0.75,0.5))) -> 0.9 | T9: =STANDARDIZE(R9,$R$26,$R$27) -> -0.22663708
B10: 44 | C10: =IF(J10=1,"බේරිය",IF(J10=2,"මණ්ඩ",IF(J10=3,"කඩොල්",IF(J10=4,"තෙලකීරිය","හීන් කඩොල්/ ඇවරි කඩොල්")))) -> බේරිය | D10: =IF(J10=1,"Lumitzera racemosa",IF(J10=2,"Avicenia marina",IF(J10=3,"Rhizophora spp.",IF(J10=4,"Excoecaria agallocha","Aegiceras corniculatum")))) -> Lumitzera racemosa | E10: 23.45 | F10: 0.54 | G10: B | J10: 1 | K10: 2 | L10: 9 | O10: =0.251*(IF(J10=1,0.7,IF(J10=2,0.58,IF(J10=3,0.62,IF(J10=4,0.45,0.55))))*E10/10*F10)^0.916 -> 0.22475381 | P10: =O10*IF(G10="A",1,IF(G10="B",0.9,IF(G10="C",0.75,0.5))) -> 0.20227843 | R10: =IF(G10="A",1,IF(G10="B",0.9,IF(G10="C",0.75,0.5))) -> 0.9 | T10: =STANDARDIZE(R10,$R$26,$R$27) -> -0.22663708
B11: 45 | C11: =IF(J11=1,"බේරිය",IF(J11=2,"මණ්ඩ",IF(J11=3,"කඩොල්",IF(J11=4,"තෙලකීරිය","හීන් කඩොල්/ ඇවරි කඩොල්")))) -> බේරිය | D11: =IF(J11=1,"Lumitzera racemosa",IF(J11=2,"Avicenia marina",IF(J11=3,"Rhizophora spp.",IF(J11=4,"Excoecaria agallocha","Aegiceras corniculatum")))) -> Lumitzera racemosa | E11: 27.27 | F11: 193 | G11: A | J11: 1 | K11: 10 | L11: 3 | O11: =0.251*(IF(J11=1,0.7,IF(J11=2,0.58,IF(J11=3,0.62,IF(J11=4,0.45,0.55))))*E11/10*F11)^0.916 -> 56.291343 | P11: =O11*IF(G11="A",1,IF(G11="B",0.9,IF(G11="C",0.75,0.5))) -> 56.291343 | R11: =IF(G11="A",1,IF(G11="B",0.9,IF(G11="C",0.75,0.5))) -> 1 | T11: =STANDARDIZE(R11,$R$26,$R$27) -> 0.5665927
B12: 46 | C12: =IF(J12=1,"බේරිය",IF(J12=2,"මණ්ඩ",IF(J12=3,"කඩොල්",IF(J12=4,"තෙලකීරිය","හීන් කඩොල්/ ඇවරි කඩොල්")))) -> බේරිය | D12: =IF(J12=1,"Lumitzera racemosa",IF(J12=2,"Avicenia marina",IF(J12=3,"Rhizophora spp.",IF(J12=4,"Excoecaria agallocha","Aegiceras corniculatum")))) -> Lumitzera racemosa | E12: 23.65 | F12: 1.37 | G12: A | J12: 1 | K12: 4 | L12: 26 | O12: =0.251*(IF(J12=1,0.7,IF(J12=2,0.58,IF(J12=3,0.62,IF(J12=4,0.45,0.55))))*E12/10*F12)^0.916 -> 0.53143346 | P12: =O12*IF(G12="A",1,IF(G12="B",0.9,IF(G12="C",0.75,0.5))) -> 0.53143346 | R12: =IF(G12="A",1,IF(G12="B",0.9,IF(G12="C",0.75,0.5))) -> 1 | T12: =STANDARDIZE(R12,$R$26,$R$27) -> 0.5665927
B13: 47 | C13: =IF(J13=1,"බේරිය",IF(J13=2,"මණ්ඩ",IF(J13=3,"කඩොල්",IF(J13=4,"තෙලකීරිය","හීන් කඩොල්/ ඇවරි කඩොල්")))) -> තෙලකීරිය | D13: =IF(J13=1,"Lumitzera racemosa",IF(J13=2,"Avicenia marina",IF(J13=3,"Rhizophora spp.",IF(J13=4,"Excoecaria agallocha","Aegiceras corniculatum")))) -> Excoecaria agallocha | E13: 28.68 | F13: 0.99 | G13: A | J13: 4 | K13: 2 | L13: 13 | O13: =0.251*(IF(J13=1,0.7,IF(J13=2,0.58,IF(J13=3,0.62,IF(J13=4,0.45,0.55))))*E13/10*F13)^0.916 -> 0.31416711 | P13: =O13*IF(G13="A",1,IF(G13="B",0.9,IF(G13="C",0.75,0.5))) -> 0.31416711 | R13: =IF(G13="A",1,IF(G13="B",0.9,IF(G13="C",0.75,0.5))) -> 1 | T13: =STANDARDIZE(R13,$R$26,$R$27) -> 0.5665927
B14: 48 | C14: =IF(J14=1,"බේරිය",IF(J14=2,"මණ්ඩ",IF(J14=3,"කඩොල්",IF(J14=4,"තෙලකීරිය","හීන් කඩොල්/ ඇවරි කඩොල්")))) -> බේරිය | D14: =IF(J14=1,"Lumitzera racemosa",IF(J14=2,"Avicenia marina",IF(J14=3,"Rhizophora spp.",IF(J14=4,"Excoecaria agallocha","Aegiceras corniculatum")))) -> Lumitzera racemosa | E14: 15.38 | F14: 0.86 | G14: B | J14: 1 | K14: 5 | L14: 7 | O14: =0.251*(IF(J14=1,0.7,IF(J14=2,0.58,IF(J14=3,0.62,IF(J14=4,0.45,0.55))))*E14/10*F14)^0.916 -> 0.23390317 | P14: =O14*IF(G14="A",1,IF(G14="B",0.9,IF(G14="C",0.75,0.5))) -> 0.21051285 | R14: =IF(G14="A",1,IF(G14="B",0.9,IF(G14="C",0.75,0.5))) -> 0.9 | T14: =STANDARDIZE(R14,$R$26,$R$27) -> -0.22663708
B15: 49 | C15: =IF(J15=1,"බේරිය",IF(J15=2,"මණ්ඩ",IF(J15=3,"කඩොල්",IF(J15=4,"තෙලකීරිය","හීන් කඩොල්/ ඇවරි කඩොල්")))) -> බේරිය | D15: =IF(J15=1,"Lumitzera racemosa",IF(J15=2,"Avicenia marina",IF(J15=3,"Rhizophora spp.",IF(J15=4,"Excoecaria agallocha","Aegiceras corniculatum")))) -> Lumitzera racemosa | E15: 32.63 | F15: 1.4 | G15: B | J15: 1 | K15: 13 | L15: 7 | O15: =0.251*(IF(J15=1,0.7,IF(J15=2,0.58,IF(J15=3,0.62,IF(J15=4,0.45,0.55))))*E15/10*F15)^0.916 -> 0.72796424 | P15: =O15*IF(G15="A",1,IF(G15="B",0.9,IF(G15="C",0.75,0.5))) -> 0.65516782 | R15: =IF(G15="A",1,IF(G15="B",0.9,IF(G15="C",0.75,0.5))) -> 0.9 | T15: =STANDARDIZE(R15,$R$26,$R$27) -> -0.22663708
B16: 50 | C16: =IF(J16=1,"බේරිය",IF(J16=2,"මණ්ඩ",IF(J16=3,"කඩොල්",IF(J16=4,"තෙලකීරිය","හීන් කඩොල්/ ඇවරි කඩොල්")))) -> බේරිය | D16: =IF(J16=1,"Lumitzera racemosa",IF(J16=2,"Avicenia marina",IF(J16=3,"Rhizophora spp.",IF(J16=4,"Excoecaria agallocha","Aegiceras corniculatum")))) -> Lumitzera racemosa | E16: 44.59 | F16: 1.37 | G16: A | J16: 1 | K16: 1 | L16: 8 | O16: =0.251*(IF(J16=1,0.7,IF(J16=2,0.58,IF(J16=3,0.62,IF(J16=4,0.45,0.55))))*E16/10*F16)^0.916 -> 0.9499945 | P16: =O16*IF(G16="A",1,IF(G16="B",0.9,IF(G16="C",0.75,0.5))) -> 0.9499945 | R16: =IF(G16="A",1,IF(G16="B",0.9,IF(G16="C",0.75,0.5))) -> 1 | T16: =STANDARDIZE(R16,$R$26,$R$27) -> 0.5665927
... B23: 57 | C23: =IF(J23=1,"බේරිය",IF(J23=2,"මණ්ඩ",IF(J23=3,"කඩොල්",IF(J23=4,"තෙලකීරිය","හීන් කඩොල්/ ඇවරි කඩොල්")))) -> බේරිය | D23: =IF(J23=1,"Lumitzera racemosa",IF(J23=2,"Avicenia marina",IF(J23=3,"Rhizophora spp.",IF(J23=4,"Excoecaria agallocha","Aegiceras corniculatum")))) -> Lumitzera racemosa | E23: 28.63 | F23: 1.5 | G23: A | J23: 1 | K23: 2 | L23: 7 | O23: =0.251*(IF(J23=1,0.7,IF(J23=2,0.58,IF(J23=3,0.62,IF(J23=4,0.45,0.55))))*E23/10*F23)^0.916 -> 0.68790976 | P23: =O23*IF(G23="A",1,IF(G23="B",0.9,IF(G23="C",0.75,0.5))) -> 0.68790976 | R23: =IF(G23="A",1,IF(G23="B",0.9,IF(G23="C",0.75,0.5))) -> 1 | T23: =STANDARDIZE(R23,$R$26,$R$27) -> 0.5665927
B24: 58 | C24: =IF(J24=1,"බේරිය",IF(J24=2,"මණ්ඩ",IF(J24=3,"කඩොල්",IF(J24=4,"තෙලකීරිය","හීන් කඩොල්/ ඇවරි කඩොල්")))) -> බේරිය | D24: =IF(J24=1,"Lumitzera racemosa",IF(J24=2,"Avicenia marina",IF(J24=3,"Rhizophora spp.",IF(J24=4,"Excoecaria agallocha","Aegiceras corniculatum")))) -> Lumitzera racemosa | E24: 34.84 | F24: 1.57 | G24: A | H24: Flowers | J24: 1 | K24: 3 | L24: 9 | O24: =0.251*(IF(J24=1,0.7,IF(J24=2,0.58,IF(J24=3,0.62,IF(J24=4,0.45,0.55))))*E24/10*F24)^0.916 -> 0.85856107 | P24: =O24*IF(G24="A",1,IF(G24="B",0.9,IF(G24="C",0.75,0.5))) -> 0.85856107 | R24: =IF(G24="A",1,IF(G24="B",0.9,IF(G24="C",0.75,0.5))) -> 1 | T24: =STANDARDIZE(R24,$R$26,$R$27) -> 0.5665927
O26: Total Adjusted AGB (Kg/plot) | P26: =SUM(P4:P24) -> 67.387459 | Q26: Avarage Tree Condition value | R26: =AVERAGE(R4:R24) -> 0.92857143
Q27: STDEV | R27: =STDEV(R4:R24) -> 0.12606688
O29: Total Biomass = AGB + BGB = AGB × (1 + 0.24)
O30: Total Biomass | P30: =1.24*P26 -> 83.56045
O33: 1 kg of dry biomass = ~1.2 kg of oxygen produced annually
O34: O₂ Produced( kg O₂/year)≈ | P34: =1.2*P30 -> 100.27254
O37: CO₂ absorbed | P37: 1 kg biomass → ~1.83 kg CO₂/year
O38: CO₂ Sequestered( kg CO₂/year)≈ | P38: =1.83*P30 -> 152.91562

Sheet Plot 3
A1: Kalpitiya Mangrove Inventory
A2: Date:03/2025
A3: Plot No | B3: Tag No | C3: Common Name | D3: Scientific Name | E3: DBH(mm) | F3: Tree Height(m) | G3: Tree Condition(A-D) | H3: Presence of Flowers/Fruits | I3: GPS | J3: Photo Numbers | K3: sub branchers (sb) | L3: branchers(b) | O3: ADG(kg/Tree) | P3: Adjusted AGB(for condition)(kg) | R3: Tree Condition Value | T3: Standadize Tree Condition
A4: 3 | B4: 59 | C4: =IF(J4=1,"බේරිය",IF(J4=2,"මණ්ඩ",IF(J4=3,"කඩොල්",IF(J4=4,"තෙලකීරිය","හීන් කඩොල්/ ඇවරි කඩොල්")))) -> බේරිය | D4: =IF(J4=1,"Lumitzera racemosa",IF(J4=2,"Avicenia marina",IF(J4=3,"Rhizophora spp.",IF(J4=4,"Excoecaria agallocha","Aegiceras corniculatum")))) -> Lumitzera racemosa | E4: 29.62 | F4: 1.7 | G4: A | J4: 1 | K4: 8 | L4: 15 | O4: =0.251*(IF(J4=1,0.7,IF(J4=2,0.58,IF(J4=3,0.62,IF(J4=4,0.45,0.55))))*E4/10*F4)^0.916 -> 0.79587827 | P4: =O4*IF(G4="A",1,IF(G4="B",0.9,IF(G4="C",0.75,0.5))) -> 0.79587827 | R4: =IF(G4="A",1,IF(G4="B",0.9,IF(G4="C",0.75,0.5))) -> 1 | T4: =STANDARDIZE(R4,$R$67,$R$68) -> 1.8617939
B5: 60 | C5: =IF(J5=1,"බේරිය",IF(J5=2,"මණ්ඩ",IF(J5=3,"කඩොල්",IF(J5=4,"තෙලකීරිය","හීන් කඩොල්/ ඇවරි කඩොල්")))) -> බේරිය | D5: =IF(J5=1,"Lumitzera racemosa",IF(J5=2,"Avicenia marina",IF(J5=3,"Rhizophora spp.",IF(J5=4,"Excoecaria agallocha","Aegiceras corniculatum")))) -> Lumitzera racemosa | E5: 33 | F5: 1.65 | G5: D | J5: 1 | K5: 4 | L5: 8 | O5: =0.251*(IF(J5=1,0.7,IF(J5=2,0.58,IF(J5=3,0.62,IF(J5=4,0.45,0.55))))*E5/10*F5)^0.916 -> 0.85498321 | P5: =O5*IF(G5="A",1,IF(G5="B",0.9,IF(G5="C",0.75,0.5))) -> 0.42749161 | R5: =IF(G5="A",1,IF(G5="B",0.9,IF(G5="C",0.75,0.5))) -> 0.5 | T5: =STANDARDIZE(R5,$R$67,$R$68) -> -0.71479587
B6: 61 | C6: =IF(J6=1,"බේරිය",IF(J6=2,"මණ්ඩ",IF(J6=3,"කඩොල්",IF(J6=4,"තෙලකීරිය","හීන් කඩොල්/ ඇවරි කඩොල්")))) -> බේරිය | D6: =IF(J6=1,"Lumitzera racemosa",IF(J6=2,"Avicenia marina",IF(J6=3,"Rhizophora spp.",IF(J6=4,"Excoecaria agallocha","Aegiceras corniculatum")))) -> Lumitzera racemosa | E6: 13.99 | F6: 0.81 | G6: D | J6: 1 | K6: 3 | L6: 6 | O6: =0.251*(IF(J6=1,0.7,IF(J6=2,0.58,IF(J6=3,0.62,IF(J6=4,0.45,0.55))))*E6/10*F6)^0.916 -> 0.20301346 | P6: =O6*IF(G6="A",1,IF(G6="B",0.9,IF(G6="C",0.75,0.5))) -> 0.10150673 | R6: =IF(G6="A",1,IF(G6="B",0.9,IF(G6="C",0.75,0.5))) -> 0.5 | T6: =STANDARDIZE(R6,$R$67,$R$68) -> -0.71479587
B7: 62 | C7: =IF(J7=1,"බේරිය",IF(J7=2,"මණ්ඩ",IF(J7=3,"කඩොල්",IF(J7=4,"තෙලකීරිය","හීන් කඩොල්/ ඇවරි කඩොල්")))) -> බේරිය | D7: =IF(J7=1,"Lumitzera racemosa",IF(J7=2,"Avicenia marina",IF(J7=3,"Rhizophora spp.",IF(J7=4,"Excoecaria agallocha","Aegiceras corniculatum")))) -> Lumitzera racemosa | E7: 28.53 | F7: 1.57 | G7: A | J7: 1 | K7: 13 | L7: 8 | O7: =0.251*(IF(J7=1,0.7,IF(J7=2,0.58,IF(J7=3,0.62,IF(J7=4,0.45,0.55))))*E7/10*F7)^0.916 -> 0.71496376 | P7: =O7*IF(G7="A",1,IF(G7="B",0.9,IF(G7="C",0.75,0.5))) -> 0.71496376 | R7: =IF(G7="A",1,IF(G7="B",0.9,IF(G7="C",0.75,0.5))) -> 1 | T7: =STANDARDIZE(R7,$R$67,$R$68) -> 1.8617939
B8: 63 | C8: =IF(J8=1,"බේරිය",IF(J8=2,"මණ්ඩ",IF(J8=3,"කඩොල්",IF(J8=4,"තෙලකීරිය","හීන් කඩොල්/ ඇවරි කඩොල්")))) -> තෙලකීරිය | D8: =IF(J8=1,"Lumitzera racemosa",IF(J8=2,"Avicenia marina",IF(J8=3,"Rhizophora spp.",IF(J8=4,"Excoecaria agallocha","Aegiceras corniculatum")))) -> Excoecaria agallocha | E8: 22.6 | F8: 1.3 | G8: A | J8: 4 | K8: 3 | L8: 8 | O8: =0.251*(IF(J8=1,0.7,IF(J8=2,0.58,IF(J8=3,0.62,IF(J8=4,0.45,0.55))))*E8/10*F8)^0.916 -> 0.32415433 | P8: =O8*IF(G8="A",1,IF(G8="B",0.9,IF(G8="C",0.75,0.5))) -> 0.32415433 | R8: =IF(G8="A",1,IF(G8="B",0.9,IF(G8="C",0.75,0.5))) -> 1 | T8: =STANDARDIZE(R8,$R$67,$R$68) -> 1.8617939
B9: 64 | C9: =IF(J9=1,"බේරිය",IF(J9=2,"මණ්ඩ",IF(J9=3,"කඩොල්",IF(J9=4,"තෙලකීරිය","හීන් කඩොල්/ ඇවරි කඩොල්")))) -> තෙලකීරිය | D9: =IF(J9=1,"Lumitzera racemosa",IF(J9=2,"Avicenia marina",IF(J9=3,"Rhizophora spp.",IF(J9=4,"Excoecaria agallocha","Aegiceras corniculatum")))) -> Excoecaria agallocha | E9: 10.26 | F9: 0.58 | G9: C | J9: 4 | K9: 1 | L9: 5 | O9: =0.251*(IF(J9=1,0.7,IF(J9=2,0.58,IF(J9=3,0.62,IF(J9=4,0.45,0.55))))*E9/10*F9)^0.916 -> 0.075080544 | P9: =O9*IF(G9="A",1,IF(G9="B",0.9,IF(G9="C",0.75,0.5))) -> 0.056310408 | R9: =IF(G9="A",1,IF(G9="B",0.9,IF(G9="C",0.75,0.5))) -> 0.75 | T9: =STANDARDIZE(R9,$R$67,$R$68) -> 0.57349901
B10: 65 | C10: =IF(J10=1,"බේරිය",IF(J10=2,"මණ්ඩ",IF(J10=3,"කඩොල්",IF(J10=4,"තෙලකීරිය","හීන් කඩොල්/ ඇවරි කඩොල්")))) -> තෙලකීරිය | D10: =IF(J10=1,"Lumitzera racemosa",IF(J10=2,"Avicenia marina",IF(J10=3,"Rhizophora spp.",IF(J10=4,"Excoecaria agallocha","Aegiceras corniculatum")))) -> Excoecaria agallocha | E10: 11.48 | F10: 0.84 | G10: B | J10: 4 | K10: 1 | L10: 10 | O10: =0.251*(IF(J10=1,0.7,IF(J10=2,0.58,IF(J10=3,0.62,IF(J10=4,0.45,0.55))))*E10/10*F10)^0.916 -> 0.11683231 | P10: =O10*IF(G10="A",1,IF(G10="B",0.9,IF(G10="C",0.75,0.5))) -> 0.10514908 | R10: =IF(G10="A",1,IF(G10="B",0.9,IF(G10="C",0.75,0.5))) -> 0.9 | T10: =STANDARDIZE(R10,$R$67,$R$68) -> 1.3464759
B11: 66 | C11: =IF(J11=1,"බේරිය",IF(J11=2,"මණ්ඩ",IF(J11=3,"කඩොල්",IF(J11=4,"තෙලකීරිය","හීන් කඩොල්/ ඇවරි කඩොල්")))) -> බේරිය | D11: =IF(J11=1,"Lumitzera racemosa",IF(J11=2,"Avicenia marina",IF(J11=3,"Rhizophora spp.",IF(J11=4,"Excoecaria agallocha","Aegiceras corniculatum")))) -> Lumitzera racemosa | E11: 8.17 | F11: 0.79 | G11: B | J11: 1 | K11: 2 | L11: 7 | O11: =0.251*(IF(J11=1,0.7,IF(J11=2,0.58,IF(J11=3,0.62,IF(J11=4,0.45,0.55))))*E11/10*F11)^0.916 -> 0.12122867 | P11: =O11*IF(G11="A",1,IF(G11="B",0.9,IF(G11="C",0.75,0.5))) -> 0.1091058 | R11: =IF(G11="A",1,IF(G11="B",0.9,IF(G11="C",0.75,0.5))) -> 0.9 | T11: =STANDARDIZE(R11,$R$67,$R$68) -> 1.3464759
B12: 67 | C12: =IF(J12=1,"බේරිය",IF(J12=2,"මණ්ඩ",IF(J12=3,"කඩොල්",IF(J12=4,"තෙලකීරිය","හීන් කඩොල්/ ඇවරි කඩොල්")))) -> බේරිය | D12: =IF(J12=1,"Lumitzera racemosa",IF(J12=2,"Avicenia marina",IF(J12=3,"Rhizophora spp.",IF(J12=4,"Excoecaria agallocha","Aegiceras corniculatum")))) -> Lumitzera racemosa | E12: 17.6 | F12: 2.13 | G12: B | J12: 1 | K12: 4 | L12: 18 | O12: =0.251*(IF(J12=1,0.7,IF(J12=2,0.58,IF(J12=3,0.62,IF(J12=4,0.45,0.55))))*E12/10*F12)^0.916 -> 0.60739169 | P12: =O12*IF(G12="A",1,IF(G12="B",0.9,IF(G12="C",0.75,0.5))) -> 0.54665252 | R12: =IF(G12="A",1,IF(G12="B",0.9,IF(G12="C",0.75,0.5))) -> 0.9 | T12: =STANDARDIZE(R12,$R$67,$R$68) -> 1.3464759
B13: 68 | C13: =IF(J13=1,"බේරිය",IF(J13=2,"මණ්ඩ",IF(J13=3,"කඩොල්",IF(J13=4,"තෙලකීරිය","හීන් කඩොල්/ ඇවරි කඩොල්")))) -> බේරිය | D13: =IF(J13=1,"Lumitzera racemosa",IF(J13=2,"Avicenia marina",IF(J13=3,"Rhizophora spp.",IF(J13=4,"Excoecaria agallocha","Aegiceras corniculatum")))) -> Lumitzera racemosa | E13: 16 | F13: 1.57 | G13: B | J13: 1 | K13: 2 | L13: 12 | O13: =0.251*(IF(J13=1,0.7,IF(J13=2,0.58,IF(J13=3,0.62,IF(J13=4,0.45,0.55))))*E13/10*F13)^0.916 -> 0.42092189 | P13: =O13*IF(G13="A",1,IF(G13="B",0.9,IF(G13="C",0.75,0.5))) -> 0.3788297 | R13: =IF(G13="A",1,IF(G13="B",0.9,IF(G13="C",0.75,0.5))) -> 0.9 | T13: =STANDARDIZE(R13,$R$67,$R$68) -> 1.3464759
B14: 69 | C14: =IF(J14=1,"බේරිය",IF(J14=2,"මණ්ඩ",IF(J14=3,"කඩොල්",IF(J14=4,"තෙලකීරිය","හීන් කඩොල්/ ඇවරි කඩොල්")))) -> තෙලකීරිය | D14: =IF(J14=1,"Lumitzera racemosa",IF(J14=2,"Avicenia marina",IF(J14=3,"Rhizophora spp.",IF(J14=4,"Excoecaria agallocha","Aegiceras corniculatum")))) -> Excoecaria agallocha | E14: 29 | F14: 0.71 | G14: C | J14: 4 | K14: 1 | L14: 5 | O14: =0.251*(IF(J14=1,0.7,IF(J14=2,0.58,IF(J14=3,0.62,IF(J14=4,0.45,0.55))))*E14/10*F14)^0.916 -> 0.23405914 | P14: =O14*IF(G14="A",1,IF(G14="B",0.9,IF(G14="C",0.75,0.5))) -> 0.17554435 | R14: =IF(G14="A",1,IF(G14="B",0.9,IF(G14="C",0.75,0.5))) -> 0.75 | T14: =STANDARDIZE(R14,$R$67,$R$68) -> 0.57349901
B15: 70 | C15: =IF(J15=1,"බේරිය",IF(J15=2,"මණ්ඩ",IF(J15=3,"කඩොල්",IF(J15=4,"තෙලකීරිය","හීන් කඩොල්/ ඇවරි කඩොල්")))) -> තෙලකීරිය | D15: =IF(J15=1,"Lumitzera racemosa",IF(J15=2,"Avicenia marina",IF(J15=3,"Rhizophora spp.",IF(J15=4,"Excoecaria agallocha","Aegiceras corniculatum")))) -> Excoecaria agallocha | E15: 16.81 | F15: 0.66 | G15: A | J15: 4 | K15: 1 | L15: 6 | O15: =0.251*(IF(J15=1,0.7,IF(J15=2,0.58,IF(J15=3,0.62,IF(J15=4,0.45,0.55))))*E15/10*F15)^0.916 -> 0.13284299 | P15: =O15*IF(G15="A",1,IF(G15="B",0.9,IF(G15="C",0.75,0.5))) -> 0.13284299 | R15: =IF(G15="A",1,IF(G15="B",0.9,IF(G15="C",0.75,0.5))) -> 1 | T15: =STANDARDIZE(R15,$R$67,$R$68) -> 1.8617939
B16: 71 | C16: =IF(J16=1,"බේරිය",IF(J16=2,"මණ්ඩ",IF(J16=3,"කඩොල්",IF(J16=4,"තෙලකීරිය","හීන් කඩොල්/ ඇවරි කඩොල්")))) -> බේරිය | D16: =IF(J16=1,"Lumitzera racemosa",IF(J16=2,"Avicenia marina",IF(J16=3,"Rhizophora spp.",IF(J16=4,"Excoecaria agallocha","Aegiceras corniculatum")))) -> Lumitzera racemosa | E16: 12.37 | F16: 1.04 | G16: D | H16: Flowers | J16: 1 | K16: 2 | L16: 22 | O16: =0.251*(IF(J16=1,0.7,IF(J16=2,0.58,IF(J16=3,0.62,IF(J16=4,0.45,0.55))))*E16/10*F16)^0.916 -> 0.22803248 | P16: =O16*IF(G16="A",1,IF(G16="B",0.9,IF(G16="C",0.75,0.5))) -> 0.11401624 | R16: =IF(G16="A",1,IF(G16="B",0.9,IF(G16="C",0.75,0.5))) -> 0.5 | T16: =STANDARDIZE(R16,$R$67,$R$68) -> -0.71479587
B17: 72 | C17: =IF(J17=1,"බේරිය",IF(J17=2,"මණ්ඩ",IF(J17=3,"කඩොල්",IF(J17=4,"තෙලකීරිය","හීන් කඩොල්/ ඇවරි කඩොල්")))) -> බේරිය | D17: =IF(J17=1,"Lumitzera racemosa",IF(J17=2,"Avicenia marina",IF(J17=3,"Rhizophora spp.",IF(J17=4,"Excoecaria agallocha","Aegiceras corniculatum")))) -> Lumitzera racemosa | E17: 25.17 | F17: 0.81 | G17: D | H17: Flowers | J17: 1 | K17: 1 | L17: 15 | O17: =0.251*(IF(J17=1,0.7,IF(J17=2,0.58,IF(J17=3,0.62,IF(J17=4,0.45,0.55))))*E17/10*F17)^0.916 -> 0.34766809 | P17: =O17*IF(G17="A",1,IF(G17="B",0.9,IF(G17="C",0.75,0.5))) -> 0.17383404 | R17: =IF(G17="A",1,IF(G17="B",0.9,IF(G17="C",0.75,0.5))) -> 0.5 | T17: =STANDARDIZE(R17,$R$67,$R$68) -> -0.71479587
B18: 73 | C18: =IF(J18=1,"බේරිය",IF(J18=2,"මණ්ඩ",IF(J18=3,"කඩොල්",IF(J18=4,"තෙලකීරිය","හීන් කඩොල්/ ඇවරි කඩොල්")))) -> බේරිය | D18: =IF(J18=1,"Lumitzera racemosa",IF(J18=2,"Avicenia marina",IF(J18=3,"Rhizophora spp.",IF(J18=4,"Excoecaria agallocha","Aegiceras corniculatum")))) -> Lumitzera racemosa | E18: 15.87 | F18: 0.84 | G18: D | J18: 1 | K18: 1 | L18: 18 | O18: =0.251*(IF(J18=1,0.7,IF(J18=2,0.58,IF(J18=3,0.62,IF(J18=4,0.45,0.55))))*E18/10*F18)^0.916 -> 0.23558727 | P18: =O18*IF(G18="A",1,IF(G18="B",0.9,IF(G18="C",0.75,0.5))) -> 0.11779363 | R18: =IF(G18="A",1,IF(G18="B",0.9,IF(G18="C",0.75,0.5))) -> 0.5 | T18: =STANDARDIZE(R18,$R$67,$R$68) -> -0.71479587
B19: 74 | C19: =IF(J19=1,"බේරිය",IF(J19=2,"මණ්ඩ",IF(J19=3,"කඩොල්",IF(J19=4,"තෙලකීරිය","හීන් කඩොල්/ ඇවරි කඩොල්")))) -> තෙලකීරිය | D19: =IF(J19=1,"Lumitzera racemosa",IF(J19=2,"Avicenia marina",IF(J19=3,"Rhizophora spp.",IF(J19=4,"Excoecaria agallocha","Aegiceras corniculatum")))) -> Excoecaria agallocha | E19: 18.36 | F19: 1.09 | G19: D | J19: 4 | K19: 1 | L19: 12 | O19: =0.251*(IF(J19=1,0.7,IF(J19=2,0.58,IF(J19=3,0.62,IF(J19=4,0.45,0.55))))*E19/10*F19)^0.916 -> 0.22803758 | P19: =O19*IF(G19="A",1,IF(G19="B",0.9,IF(G19="C",0.75,0.5))) -> 0.11401879 | R19: =IF(G19="A",1,IF(G19="B",0.9,IF(G19="C",0.75,0.5))) -> 0.5 | T19: =STANDARDIZE(R19,$R$67,$R$68) -> -0.71479587
B20: 75 | C20: =IF(J20=1,"බේරිය",IF(J20=2,"මණ්ඩ",IF(J20=3,"කඩොල්",IF(J20=4,"තෙලකීරිය","හීන් කඩොල්/ ඇවරි කඩොල්")))) -> බේරිය | D20: =IF(J20=1,"Lumitzera racemosa",IF(J20=2,"Avicenia marina",IF(J20=3,"Rhizophora spp.",IF(J20=4,"Excoecaria agallocha","Aegiceras corniculatum")))) -> Lumitzera racemosa | E20: 46.88 | F20: 1.07 | G20: D | J20: 1 | K20: 1 | L20: 9 | O20: =0.251*(IF(J20=1,0.7,IF(J20=2,0.58,IF(J20=3,0.62,IF(J20=4,0.45,0.55))))*E20/10*F20)^0.916 -> 0.79309226 | P20: =O20*IF(G20="A",1,IF(G20="B",0.9,IF(G20="C",0.75,0.5))) -> 0.39654613 | R20: =IF(G20="A",1,IF(G20="B",0.9,IF(G20="C",0.75,0.5))) -> 0.5 | T20: =STANDARDIZE(R20,$R$67,$R$68) -> -0.71479587
B21: 76 | C21: =IF(J21=1,"බේරිය",IF(J21=2,"මණ්ඩ",IF(J21=3,"කඩොල්",IF(J21=4,"තෙලකීරිය","හීන් කඩොල්/ ඇවරි කඩොල්")))) -> තෙලකීරිය | D21: =IF(J21=1,"Lumitzera racemosa",IF(J21=2,"Avicenia marina",IF(J21=3,"Rhizophora spp.",IF(J21=4,"Excoecaria agallocha","Aegiceras corniculatum")))) -> Excoecaria agallocha | E21: 31.7 | F21: 0.79 | G21: D | J21: 4 | K21: 1 | L21: 7 | O21: =0.251*(IF(J21=1,0.7,IF(J21=2,0.58,IF(J21=3,0.62,IF(J21=4,0.45,0.55))))*E21/10*F21)^0.916 -> 0.2800355 | P21: =O21*IF(G21="A",1,IF(G21="B",0.9,IF(G21="C",0.75,0.5))) -> 0.14001775 | R21: =IF(G21="A",1,IF(G21="B",0.9,IF(G21="C",0.75,0.5))) -> 0.5 | T21: =STANDARDIZE(R21,$R$67,$R$68) -> -0.71479587
B22: 77 | C22: =IF(J22=1,"බේරිය",IF(J22=2,"මණ්ඩ",IF(J22=3,"කඩොල්",IF(J22=4,"තෙලකීරිය","හීන් කඩොල්/ ඇවරි කඩොල්")))) -> තෙලකීරිය | D22: =IF(J22=1,"Lumitzera racemosa",IF(J22=2,"Avicenia marina",IF(J22=3,"Rhizophora spp.",IF(J22=4,"Excoecaria agallocha","Aegiceras corniculatum")))) -> Excoecaria agallocha | E22: 28.85 | F22: 1.07 | G22: D | J22: 4 | K22: 1 | L22: 13 | O22: =0.251*(IF(J22=1,0.7,IF(J22=2,0.58,IF(J22=3,0.62,IF(J22=4,0.45,0.55))))*E22/10*F22)^0.916 -> 0.3391763 | P22: =O22*IF(G22="A",1,IF(G22="B",0.9,IF(G22="C",0.75,0.5))) -> 0.16958815 | R22: =IF(G22="A",1,IF(G22="B",0.9,IF(G22="C",0.75,0.5))) -> 0.5 | T22: =STANDARDIZE(R22,$R$67,$R$68) -> -0.71479587
B23: 78 | C23: =IF(J23=1,"බේරිය",IF(J23=2,"මණ්ඩ",IF(J23=3,"කඩොල්",IF(J23=4,"තෙලකීරිය","හීන් කඩොල්/ ඇවරි කඩොල්")))) -> බේරිය | D23: =IF(J23=1,"Lumitzera racemosa",IF(J23=2,"Avicenia marina",IF(J23=3,"Rhizophora spp.",IF(J23=4,"Excoecaria agallocha","Aegiceras corniculatum")))) -> Lumitzera racemosa | E23: 33.86 | F23: 1.09 | G23: D | J23: 1 | K23: 1 | L23: 13 | O23: =0.251*(IF(J23=1,0.7,IF(J23=2,0.58,IF(J23=3,0.62,IF(J23=4,0.45,0.55))))*E23/10*F23)^0.916 -> 0.59876919 | P23: =O23*IF(G23="A",1,IF(G23="B",0.9,IF(G23="C",0.75,0.5))) -> 0.2993846 | R23: =IF(G23="A",1,IF(G23="B",0.9,IF(G23="C",0.75,0.5))) -> 0.5 | T23: =STANDARDIZE(R23,$R$67,$R$68) -> -0.71479587
B24: 79 | C24: =IF(J24=1,"බේරිය",IF(J24=2,"මණ්ඩ",IF(J24=3,"කඩොල්",IF(J24=4,"තෙලකීරිය","හීන් කඩොල්/ ඇවරි කඩොල්")))) -> බේරිය | D24: =IF(J24=1,"Lumitzera racemosa",IF(J24=2,"Avicenia marina",IF(J24=3,"Rhizophora spp.",IF(J24=4,"Excoecaria agallocha","Aegiceras corniculatum")))) -> Lumitzera racemosa | E24: 14.53 | F24: 1.04 | G24: D | J24: 1 | K24: 1 | L24: 10 | O24: =0.251*(IF(J24=1,0.7,IF(J24=2,0.58,IF(J24=3,0.62,IF(J24=4,0.45,0.55))))*E24/10*F24)^0.916 -> 0.26425388 | P24: =O24*IF(G24="A",1,IF(G24="B",0.9,IF(G24="C",0.75,0.5))) -> 0.13212694 | R24: =IF(G24="A",1,IF(G24="B",0.9,IF(G24="C",0.75,0.5))) -> 0.5 | T24: =STANDARDIZE(R24,$R$67,$R$68) -> -0.71479587
B25: 80 | C25: =IF(J25=1,"බේරිය",IF(J25=2,"මණ්ඩ",IF(J25=3,"කඩොල්",IF(J25=4,"තෙලකීරිය","හීන් කඩොල්/ ඇවරි කඩොල්")))) -> බේරිය | D25: =IF(J25=1,"Lumitzera racemosa",IF(J25=2,"Avicenia marina",IF(J25=3,"Rhizophora spp.",IF(J25=4,"Excoecaria agallocha","Aegiceras corniculatum")))) -> Lumitzera racemosa | E25: 10.64 | F25: 0.71 | G25: D | J25: 1 | K25: 1 | L25: 9 | O25: =0.251*(IF(J25=1,0.7,IF(J25=2,0.58,IF(J25=3,0.62,IF(J25=4,0.45,0.55))))*E25/10*F25)^0.916 -> 0.14002794 | P25: =O25*IF(G25="A",1,IF(G25="B",0.9,IF(G25="C",0.75,0.5))) -> 0.070013971 | R25: =IF(G25="A",1,IF(G25="B",0.9,IF(G25="C",0.75,0.5))) -> 0.5 | T25: =STANDARDIZE(R25,$R$67,$R$68) -> -0.71479587
B26: 81 | C26: =IF(J26=1,"බේරිය",IF(J26=2,"මණ්ඩ",IF(J26=3,"කඩොල්",IF(J26=4,"තෙලකීරිය","හීන් කඩොල්/ ඇවරි කඩොල්")))) -> බේරිය | D26: =IF(J26=1,"Lumitzera racemosa",IF(J26=2,"Avicenia marina",IF(J26=3,"Rhizophora spp.",IF(J26=4,"Excoecaria agallocha","Aegiceras corniculatum")))) -> Lumitzera racemosa | E26: 14.48 | F26: 1.09 | G26: D | J26: 1 | K26: 1 | L26: 12 | O26: =0.251*(IF(J26=1,0.7,IF(J26=2,0.58,IF(J26=3,0.62,IF(J26=4,0.45,0.55))))*E26/10*F26)^0.916 -> 0.27499842 | P26: =O26*IF(G26="A",1,IF(G26="B",0.9,IF(G26="C",0.75,0.5))) -> 0.13749921 | R26: =IF(G26="A",1,IF(G26="B",0.9,IF(G26="C",0.75,0.5))) -> 0.5 | T26: =STANDARDIZE(R26,$R$67,$R$68) -> -0.71479587
B27: 82 | C27: =IF(J27=1,"බේරිය",IF(J27=2,"මණ්ඩ",IF(J27=3,"කඩොල්",IF(J27=4,"තෙලකීරිය","හීන් කඩොල්/ ඇවරි කඩොල්")))) -> තෙලකීරිය | D27: =IF(J27=1,"Lumitzera racemosa",IF(J27=2,"Avicenia marina",IF(J27=3,"Rhizophora spp.",IF(J27=4,"Excoecaria agallocha","Aegiceras corniculatum")))) -> Excoecaria agallocha | E27: 42.81 | F27: 1.19 | G27: D | J27: 4 | K27: 1 | L27: 14 | O27: =0.251*(IF(J27=1,0.7,IF(J27=2,0.58,IF(J27=3,0.62,IF(J27=4,0.45,0.55))))*E27/10*F27)^0.916 -> 0.53667681 | P27: =O27*IF(G27="A",1,IF(G27="B",0.9,IF(G27="C",0.75,0.5))) -> 0.2683384 | R27: =IF(G27="A",1,IF(G27="B",0.9,IF(G27="C",0.75,0.5))) -> 0.5 | T27: =STANDARDIZE(R27,$R$67,$R$68) -> -0.71479587
B28: 83 | C28: =IF(J28=1,"බේරිය",IF(J28=2,"මණ්ඩ",IF(J28=3,"කඩොල්",IF(J28=4,"තෙලකීරිය","හීන් කඩොල්/ ඇවරි කඩොල්")))) -> තෙලකීරිය | D28: =IF(J28=1,"Lumitzera racemosa",IF(J28=2,"Avicenia marina",IF(J28=3,"Rhizophora spp.",IF(J28=4,"Excoecaria agallocha","Aegiceras corniculatum")))) -> Excoecaria agallocha | E28: 12.82 | F28: 0.94 | G28: D | J28: 4 | K28: 2 | L28: 5 | O28: =0.251*(IF(J28=1,0.7,IF(J28=2,0.58,IF(J28=3,0.62,IF(J28=4,0.45,0.55))))*E28/10*F28)^0.916 -> 0.14329364 | P28: =O28*IF(G28="A",1,IF(G28="B",0.9,IF(G28="C",0.75,0.5))) -> 0.071646822 | R28: =IF(G28="A",1,IF(G28="B",0.9,IF(G28="C",0.75,0.5))) -> 0.5 | T28: =STANDARDIZE(R28,$R$67,$R$68) -> -0.71479587
B29: 84 | C29: =IF(J29=1,"බේරිය",IF(J29=2,"මණ්ඩ",IF(J29=3,"කඩොල්",IF(J29=4,"තෙලකීරිය","හීන් කඩොල්/ ඇවරි කඩොල්")))) -> බේරිය | D29: =IF(J29=1,"Lumitzera racemosa",IF(J29=2,"Avicenia marina",IF(J29=3,"Rhizophora spp.",IF(J29=4,"Excoecaria agallocha","Aegiceras corniculatum")))) -> Lumitzera racemosa | E29: 13.11 | F29: 0.94 | G29: D | J29: 1 | K29: 1 | L29: 8 | O29: =0.251*(IF(J29=1,0.7,IF(J29=2,0.58,IF(J29=3,0.62,IF(J29=4,0.45,0.55))))*E29/10*F29)^0.916 -> 0.21922633 | P29: =O29*IF(G29="A",1,IF(G29="B",0.9,IF(G29="C",0.75,0.5))) -> 0.10961316 | R29: =IF(G29="A",1,IF(G29="B",0.9,IF(G29="C",0.75,0.5))) -> 0.5 | T29: =STANDARDIZE(R29,$R$67,$R$68) -> -0.71479587
... B65: 120 | C65: =IF(J65=1,"බේරිය",IF(J65=2,"මණ්ඩ",IF(J65=3,"කඩොල්",IF(J65=4,"තෙලකීරිය","හීන් කඩොල්/ ඇවරි කඩොල්")))) -> බේරිය | D65: =IF(J65=1,"Lumitzera racemosa",IF(J65=2,"Avicenia marina",IF(J65=3,"Rhizophora spp.",IF(J65=4,"Excoecaria agallocha","Aegiceras corniculatum")))) -> Lumitzera racemosa | E65: 21.13 | F65: 0.91 | G65: B | J65: 1 | K65: 1 | L65: 11 | O65: =0.251*(IF(J65=1,0.7,IF(J65=2,0.58,IF(J65=3,0.62,IF(J65=4,0.45,0.55))))*E65/10*F65)^0.916 -> 0.32951363 | P65: =O65*IF(G65="A",1,IF(G65="B",0.9,IF(G65="C",0.75,0.5))) -> 0.29656227 | R65: =IF(G65="A",1,IF(G65="B",0.9,IF(G65="C",0.75,0.5))) -> 0.9 | T65: =STANDARDIZE(R65,$R$67,$R$68) -> 1.3464759
O67: Total Adjusted AGB (Kg/plot) | P67: =SUM(P4:P65) -> 12.777699 | Q67: Avarage Tree Condition value | R67: =AVERAGE(R4:R65) -> 0.63870968
Q68: STDEV | R68: =STDEV(R4:R65) -> 0.19405495
O70: Total Biomass = AGB + BGB = AGB × (1 + 0.24)
O71: Total Biomass | P71: =1.24*P67 -> 15.844346
O74: 1 kg of dry biomass = ~1.2 kg of oxygen produced annually
O75: O₂ Produced( kg O₂/year)≈ | P75: =1.2*P71 -> 19.013216
O78: CO₂ absorbed | P78: 1 kg biomass → ~1.83 kg CO₂/year
O79: CO₂ Sequestered( kg CO₂/year)≈ | P79: =1.83*P71 -> 28.995154

Sheet Plot 4
A1: Kalpitiya Mangrove Inventory
A2: Date:03/2025
A3: Plot No | B3: Tag No | C3: Common Name | D3: Scientific Name | E3: DBH(mm) | F3: Tree Height(m) | G3: Tree Condition(A-D) | H3: Presence of Flowers/Fruits | I3: GPS | J3: Photo Numbers | K3: sub branchers (sb) | L3: branchers(b) | O3: ADG(kg/Tree) | P3: Adjusted AGB(for condition)(kg) | R3: Tree Condition Value | T3: Standadize Tree Condition
A4: 4 | B4: 121 | C4: =IF(J4=1,"බේරිය",IF(J4=2,"මණ්ඩ",IF(J4=3,"කඩොල්",IF(J4=4,"තෙලකීරිය","හීන් කඩොල්/ ඇවරි කඩොල්")))) -> හීන් කඩොල්/ ඇවරි කඩොල් | D4: =IF(J4=1,"Lumitzera racemosa",IF(J4=2,"Avicenia marina",IF(J4=3,"Rhizophora spp.",IF(J4=4,"Excoecaria agallocha","Aegiceras corniculatum")))) -> Aegiceras corniculatum | E4: 11.83 | F4: 0.91 | G4: B | J4: 6 | K4: 1 | L4: 5 | O4: =0.251*(IF(J4=1,0.7,IF(J4=2,0.58,IF(J4=3,0.62,IF(J4=4,0.45,0.55))))*E4/10*F4)^0.916 -> 0.15530373 | P4: =O4*IF(G4="A",1,IF(G4="B",0.9,IF(G4="C",0.75,0.5))) -> 0.13977336 | R4: =IF(G4="A",1,IF(G4="B",0.9,IF(G4="C",0.75,0.5))) -> 0.9 | T4: =STANDARDIZE(R4,$R$23,$R$24) -> 0.23570226
B5: 122 | C5: =IF(J5=1,"බේරිය",IF(J5=2,"මණ්ඩ",IF(J5=3,"කඩොල්",IF(J5=4,"තෙලකීරිය","හීන් කඩොල්/ ඇවරි කඩොල්")))) -> මණ්ඩ | D5: =IF(J5=1,"Lumitzera racemosa",IF(J5=2,"Avicenia marina",IF(J5=3,"Rhizophora spp.",IF(J5=4,"Excoecaria agallocha","Aegiceras corniculatum")))) -> Avicenia marina | E5: 13.28 | F5: 0.58 | G5: B | J5: 2 | K5: 3 | L5: 12 | O5: =0.251*(IF(J5=1,0.7,IF(J5=2,0.58,IF(J5=3,0.62,IF(J5=4,0.45,0.55))))*E5/10*F5)^0.916 -> 0.11998397 | P5: =O5*IF(G5="A",1,IF(G5="B",0.9,IF(G5="C",0.75,0.5))) -> 0.10798558 | R5: =IF(G5="A",1,IF(G5="B",0.9,IF(G5="C",0.75,0.5))) -> 0.9 | T5: =STANDARDIZE(R5,$R$23,$R$24) -> 0.23570226
B6: 123 | C6: =IF(J6=1,"බේරිය",IF(J6=2,"මණ්ඩ",IF(J6=3,"කඩොල්",IF(J6=4,"තෙලකීරිය","හීන් කඩොල්/ ඇවරි කඩොල්")))) -> හීන් කඩොල්/ ඇවරි කඩොල් | D6: =IF(J6=1,"Lumitzera racemosa",IF(J6=2,"Avicenia marina",IF(J6=3,"Rhizophora spp.",IF(J6=4,"Excoecaria agallocha","Aegiceras corniculatum")))) -> Aegiceras corniculatum | E6: 15.82 | F6: 0.56 | G6: B | J6: 6 | K6: 2 | L6: 6 | O6: =0.251*(IF(J6=1,0.7,IF(J6=2,0.58,IF(J6=3,0.62,IF(J6=4,0.45,0.55))))*E6/10*F6)^0.916 -> 0.129915 | P6: =O6*IF(G6="A",1,IF(G6="B",0.9,IF(G6="C",0.75,0.5))) -> 0.1169235 | R6: =IF(G6="A",1,IF(G6="B",0.9,IF(G6="C",0.75,0.5))) -> 0.9 | T6: =STANDARDIZE(R6,$R$23,$R$24) -> 0.23570226
B7: 124 | C7: =IF(J7=1,"බේරිය",IF(J7=2,"මණ්ඩ",IF(J7=3,"කඩොල්",IF(J7=4,"තෙලකීරිය","හීන් කඩොල්/ ඇවරි කඩොල්")))) -> බේරිය | D7: =IF(J7=1,"Lumitzera racemosa",IF(J7=2,"Avicenia marina",IF(J7=3,"Rhizophora spp.",IF(J7=4,"Excoecaria agallocha","Aegiceras corniculatum")))) -> Lumitzera racemosa | E7: 11.1 | F7: 0.58 | G7: B | J7: 1 | K7: 3 | L7: 10 | O7: =0.251*(IF(J7=1,0.7,IF(J7=2,0.58,IF(J7=3,0.62,IF(J7=4,0.45,0.55))))*E7/10*F7)^0.916 -> 0.1209482 | P7: =O7*IF(G7="A",1,IF(G7="B",0.9,IF(G7="C",0.75,0.5))) -> 0.10885338 | R7: =IF(G7="A",1,IF(G7="B",0.9,IF(G7="C",0.75,0.5))) -> 0.9 | T7: =STANDARDIZE(R7,$R$23,$R$24) -> 0.23570226
B8: 125 | C8: =IF(J8=1,"බේරිය",IF(J8=2,"මණ්ඩ",IF(J8=3,"කඩොල්",IF(J8=4,"තෙලකීරිය","හීන් කඩොල්/ ඇවරි කඩොල්")))) -> හීන් කඩොල්/ ඇවරි කඩොල් | D8: =IF(J8=1,"Lumitzera racemosa",IF(J8=2,"Avicenia marina",IF(J8=3,"Rhizophora spp.",IF(J8=4,"Excoecaria agallocha","Aegiceras corniculatum")))) -> Aegiceras corniculatum | E8: 15.78 | F8: 0.76 | G8: B | J8: 6 | K8: 1 | L8: 1 | O8: =0.251*(IF(J8=1,0.7,IF(J8=2,0.58,IF(J8=3,0.62,IF(J8=4,0.45,0.55))))*E8/10*F8)^0.916 -> 0.17144989 | P8: =O8*IF(G8="A",1,IF(G8="B",0.9,IF(G8="C",0.75,0.5))) -> 0.1543049 | R8: =IF(G8="A",1,IF(G8="B",0.9,IF(G8="C",0.75,0.5))) -> 0.9 | T8: =STANDARDIZE(R8,$R$23,$R$24) -> 0.23570226
B9: 126 | C9: =IF(J9=1,"බේරිය",IF(J9=2,"මණ්ඩ",IF(J9=3,"කඩොල්",IF(J9=4,"තෙලකීරිය","හීන් කඩොල්/ ඇවරි කඩොල්")))) -> හීන් කඩොල්/ ඇවරි කඩොල් | D9: =IF(J9=1,"Lumitzera racemosa",IF(J9=2,"Avicenia marina",IF(J9=3,"Rhizophora spp.",IF(J9=4,"Excoecaria agallocha","Aegiceras corniculatum")))) -> Aegiceras corniculatum | E9: 13.71 | F9: 1.04 | G9: B | J9: 6 | K9: 2 | L9: 5 | O9: =0.251*(IF(J9=1,0.7,IF(J9=2,0.58,IF(J9=3,0.62,IF(J9=4,0.45,0.55))))*E9/10*F9)^0.916 -> 0.20089762 | P9: =O9*IF(G9="A",1,IF(G9="B",0.9,IF(G9="C",0.75,0.5))) -> 0.18080786 | R9: =IF(G9="A",1,IF(G9="B",0.9,IF(G9="C",0.75,0.5))) -> 0.9 | T9: =STANDARDIZE(R9,$R$23,$R$24) -> 0.23570226
B10: 127 | C10: =IF(J10=1,"බේරිය",IF(J10=2,"මණ්ඩ",IF(J10=3,"කඩොල්",IF(J10=4,"තෙලකීරිය","හීන් කඩොල්/ ඇවරි කඩොල්")))) -> හීන් කඩොල්/ ඇවරි කඩොල් | D10: =IF(J10=1,"Lumitzera racemosa",IF(J10=2,"Avicenia marina",IF(J10=3,"Rhizophora spp.",IF(J10=4,"Excoecaria agallocha","Aegiceras corniculatum")))) -> Aegiceras corniculatum | E10: 14.63 | F10: 1 | G10: B | J10: 6 | K10: 1 | L10: 4 | O10: =0.251*(IF(J10=1,0.7,IF(J10=2,0.58,IF(J10=3,0.62,IF(J10=4,0.45,0.55))))*E10/10*F10)^0.916 -> 0.20568838 | P10: =O10*IF(G10="A",1,IF(G10="B",0.9,IF(G10="C",0.75,0.5))) -> 0.18511954 | R10: =IF(G10="A",1,IF(G10="B",0.9,IF(G10="C",0.75,0.5))) -> 0.9 | T10: =STANDARDIZE(R10,$R$23,$R$24) -> 0.23570226
B11: 128 | C11: =IF(J11=1,"බේරිය",IF(J11=2,"මණ්ඩ",IF(J11=3,"කඩොල්",IF(J11=4,"තෙලකීරිය","හීන් කඩොල්/ ඇවරි කඩොල්")))) -> හීන් කඩොල්/ ඇවරි කඩොල් | D11: =IF(J11=1,"Lumitzera racemosa",IF(J11=2,"Avicenia marina",IF(J11=3,"Rhizophora spp.",IF(J11=4,"Excoecaria agallocha","Aegiceras corniculatum")))) -> Aegiceras corniculatum | E11: 11.03 | F11: 0.71 | G11: B | J11: 6 | K11: 1 | L11: 2 | O11: =0.251*(IF(J11=1,0.7,IF(J11=2,0.58,IF(J11=3,0.62,IF(J11=4,0.45,0.55))))*E11/10*F11)^0.916 -> 0.11603734 | P11: =O11*IF(G11="A",1,IF(G11="B",0.9,IF(G11="C",0.75,0.5))) -> 0.10443361 | R11: =IF(G11="A",1,IF(G11="B",0.9,IF(G11="C",0.75,0.5))) -> 0.9 | T11: =STANDARDIZE(R11,$R$23,$R$24) -> 0.23570226
B12: 129 | C12: =IF(J12=1,"බේරිය",IF(J12=2,"මණ්ඩ",IF(J12=3,"කඩොල්",IF(J12=4,"තෙලකීරිය","හීන් කඩොල්/ ඇවරි කඩොල්")))) -> බේරිය | D12: =IF(J12=1,"Lumitzera racemosa",IF(J12=2,"Avicenia marina",IF(J12=3,"Rhizophora spp.",IF(J12=4,"Excoecaria agallocha","Aegiceras corniculatum")))) -> Lumitzera racemosa | E12: 15.08 | F12: 1.27 | G12: B | J12: 1 | K12: 8 | L12: 10 | O12: =0.251*(IF(J12=1,0.7,IF(J12=2,0.58,IF(J12=3,0.62,IF(J12=4,0.45,0.55))))*E12/10*F12)^0.916 -> 0.32830943 | P12: =O12*IF(G12="A",1,IF(G12="B",0.9,IF(G12="C",0.75,0.5))) -> 0.29547849 | R12: =IF(G12="A",1,IF(G12="B",0.9,IF(G12="C",0.75,0.5))) -> 0.9 | T12: =STANDARDIZE(R12,$R$23,$R$24) -> 0.23570226
B13: 134 | C13: =IF(J13=1,"බේරිය",IF(J13=2,"මණ්ඩ",IF(J13=3,"කඩොල්",IF(J13=4,"තෙලකීරිය","හීන් කඩොල්/ ඇවරි කඩොල්")))) -> හීන් කඩොල්/ ඇවරි කඩොල් | D13: =IF(J13=1,"Lumitzera racemosa",IF(J13=2,"Avicenia marina",IF(J13=3,"Rhizophora spp.",IF(J13=4,"Excoecaria agallocha","Aegiceras corniculatum")))) -> Aegiceras corniculatum | E13: 12.57 | F13: 0.64 | G13: B | J13: 6 | K13: 1 | L13: 1 | O13: =0.251*(IF(J13=1,0.7,IF(J13=2,0.58,IF(J13=3,0.62,IF(J13=4,0.45,0.55))))*E13/10*F13)^0.916 -> 0.11893178 | P13: =O13*IF(G13="A",1,IF(G13="B",0.9,IF(G13="C",0.75,0.5))) -> 0.1070386 | R13: =IF(G13="A",1,IF(G13="B",0.9,IF(G13="C",0.75,0.5))) -> 0.9 | T13: =STANDARDIZE(R13,$R$23,$R$24) -> 0.23570226
B14: 135 | C14: =IF(J14=1,"බේරිය",IF(J14=2,"මණ්ඩ",IF(J14=3,"කඩොල්",IF(J14=4,"තෙලකීරිය","හීන් කඩොල්/ ඇවරි කඩොල්")))) -> තෙලකීරිය | D14: =IF(J14=1,"Lumitzera racemosa",IF(J14=2,"Avicenia marina",IF(J14=3,"Rhizophora spp.",IF(J14=4,"Excoecaria agallocha","Aegiceras corniculatum")))) -> Excoecaria agallocha | E14: 70 | F14: 2.35 | G14: B | J14: 4 | K14: 3 | L14: 6 | O14: =0.251*(IF(J14=1,0.7,IF(J14=2,0.58,IF(J14=3,0.62,IF(J14=4,0.45,0.55))))*E14/10*F14)^0.916 -> 1.5704509 | P14: =O14*IF(G14="A",1,IF(G14="B",0.9,IF(G14="C",0.75,0.5))) -> 1.4134058 | R14: =IF(G14="A",1,IF(G14="B",0.9,IF(G14="C",0.75,0.5))) -> 0.9 | T14: =STANDARDIZE(R14,$R$23,$R$24) -> 0.23570226
B15: 136 | C15: =IF(J15=1,"බේරිය",IF(J15=2,"මණ්ඩ",IF(J15=3,"කඩොල්",IF(J15=4,"තෙලකීරිය","හීන් කඩොල්/ ඇවරි කඩොල්")))) -> හීන් කඩොල්/ ඇවරි කඩොල් | D15: =IF(J15=1,"Lumitzera racemosa",IF(J15=2,"Avicenia marina",IF(J15=3,"Rhizophora spp.",IF(J15=4,"Excoecaria agallocha","Aegiceras corniculatum")))) -> Aegiceras corniculatum | E15: 11.45 | F15: 1.3 | G15: B | J15: 6 | K15: 1 | L15: 1 | O15: =0.251*(IF(J15=1,0.7,IF(J15=2,0.58,IF(J15=3,0.62,IF(J15=4,0.45,0.55))))*E15/10*F15)^0.916 -> 0.20896997 | P15: =O15*IF(G15="A",1,IF(G15="B",0.9,IF(G15="C",0.75,0.5))) -> 0.18807297 | R15: =IF(G15="A",1,IF(G15="B",0.9,IF(G15="C",0.75,0.5))) -> 0.9 | T15: =STANDARDIZE(R15,$R$23,$R$24) -> 0.23570226
B16: 137 | C16: =IF(J16=1,"බේරිය",IF(J16=2,"මණ්ඩ",IF(J16=3,"කඩොල්",IF(J16=4,"තෙලකීරිය","හීන් කඩොල්/ ඇවරි කඩොල්")))) -> හීන් කඩොල්/ ඇවරි කඩොල් | D16: =IF(J16=1,"Lumitzera racemosa",IF(J16=2,"Avicenia marina",IF(J16=3,"Rhizophora spp.",IF(J16=4,"Excoecaria agallocha","Aegiceras corniculatum")))) -> Aegiceras corniculatum | E16: 15.14 | F16: 0.79 | G16: B | J16: 6 | K16: 1 | L16: 1 | O16: =0.251*(IF(J16=1,0.7,IF(J16=2,0.58,IF(J16=3,0.62,IF(J16=4,0.45,0.55))))*E16/10*F16)^0.916 -> 0.17102818 | P16: =O16*IF(G16="A",1,IF(G16="B",0.9,IF(G16="C",0.75,0.5))) -> 0.15392536 | R16: =IF(G16="A",1,IF(G16="B",0.9,IF(G16="C",0.75,0.5))) -> 0.9 | T16: =STANDARDIZE(R16,$R$23,$R$24) -> 0.23570226
... B21: 138 | C21: =IF(J21=1,"බේරිය",IF(J21=2,"මණ්ඩ",IF(J21=3,"කඩොල්",IF(J21=4,"තෙලකීරිය","හීන් කඩොල්/ ඇවරි කඩොල්")))) -> බේරිය | D21: =IF(J21=1,"Lumitzera racemosa",IF(J21=2,"Avicenia marina",IF(J21=3,"Rhizophora spp.",IF(J21=4,"Excoecaria agallocha","Aegiceras corniculatum")))) -> Lumitzera racemosa | E21: 10.43 | F21: 0.46 | G21: B | J21: 1 | K21: 6 | L21: 5 | O21: =0.251*(IF(J21=1,0.7,IF(J21=2,0.58,IF(J21=3,0.62,IF(J21=4,0.45,0.55))))*E21/10*F21)^0.916 -> 0.092388545 | P21: =O21*IF(G21="A",1,IF(G21="B",0.9,IF(G21="C",0.75,0.5))) -> 0.08314969 | R21: =IF(G21="A",1,IF(G21="B",0.9,IF(G21="C",0.75,0.5))) -> 0.9 | T21: =STANDARDIZE(R21,$R$23,$R$24) -> 0.23570226
O23: Total Adjusted AGB (Kg/plot) | P23: =SUM(P4:P21) -> 4.0045066 | Q23: Avarage Tree Condition value | R23: =AVERAGE(R4:R21) -> 0.89166667
Q24: STDEV | R24: =STDEV(R4:R21) -> 0.035355339
O26: Total Biomass = AGB + BGB = AGB × (1 + 0.24)
O27: Total Biomass | P27: =1.24*P23 -> 4.9655882
O30: 1 kg of dry biomass = ~1.2 kg of oxygen produced annually
O31: O₂ Produced( kg O₂/year)≈ | P31: =1.2*P27 -> 5.9587059
O34: CO₂ absorbed | P34: 1 kg biomass → ~1.83 kg CO₂/year
O35: CO₂ Sequestered( kg CO₂/year)≈ | P35: =1.83*P27 -> 9.0870264

Sheet Plot 5
A1: Kalpitiya Mangrove Inventory
A2: Date:03/2025
A3: Plot No | B3: Tag No | C3: Common Name | D3: Scientific Name | E3: Grith(cm) | F3: Tree Height(m) | G3: Tree Condition(A-D) | H3: Presence of Flowers/Fruits | I3: GPS | J3: Photo Numbers | K3: sub branchers (sb) | L3: branchers(b) | M3: DBH(mm) | O3: ADG(kg/Tree) | P3: Adjusted AGB(for condition)(kg) | R3: Tree Condition Value | T3: Standadize Tree Condition
A4: 5 | B4: 139 | C4: =IF(J4=1,"බේරිය",IF(J4=2,"මණ්ඩ",IF(J4=3,"කඩොල්",IF(J4=4,"තෙලකීරිය","හීන් කඩොල්/ ඇවරි කඩොල්")))) -> මණ්ඩ | D4: =IF(J4=1,"Lumitzera racemosa",IF(J4=2,"Avicenia marina",IF(J4=3,"Rhizophora spp.",IF(J4=4,"Excoecaria agallocha","Aegiceras corniculatum")))) -> Avicenia marina | E4: 16 | F4: 3.5 | G4: B | J4: 2 | M4: =10*E4/PI() -> 50.929582 | O4: =0.251*(IF(J4=1,0.7,IF(J4=2,0.58,IF(J4=3,0.62,IF(J4=4,0.45,0.55))))*M4/10*F4)^0.916 -> 2.1326752 | P4: =O4*IF(G4="A",1,IF(G4="B",0.9,IF(G4="C",0.75,0.5))) -> 1.9194077 | R4: =IF(G4="A",1,IF(G4="B",0.9,IF(G4="C",0.75,0.5))) -> 0.9 | T4: =STANDARDIZE(R4,$R$62,$R$63) -> 0.17153731
